 path('ticket/', include("ticket.urls"))
                    ^^^^^^^^^^^^^^^^^^^^^^
  File "C:\Users\Administrator\AppData\Local\Programs\Python\Python312\Lib\site-packages\django\urls\conf.py", line 39, in include
    urlconf_module = import_module(urlconf_module)
                     ^^^^^^^^^^^^^^^^^^^^^^^^^^^^^
  File "C:\Users\Administrator\AppData\Local\Programs\Python\Python312\Lib\importlib\__init__.py", line 90, in import_module
    return _bootstrap._gcd_import(name[level:], package, level)
           ^^^^^^^^^^^^^^^^^^^^^^^^^^^^^^^^^^^^^^^^^^^^^^^^^^^^
  File "<frozen importlib._bootstrap>", line 1387, in _gcd_import
  File "<frozen importlib._bootstrap>", line 1360, in _find_and_load
  File "<frozen importlib._bootstrap>", line 1331, in _find_and_load_unlocked
  File "<frozen importlib._bootstrap>", line 935, in _load_unlocked
  File "<frozen importlib._bootstrap_external>", line 995, in exec_module
  File "<frozen importlib._bootstrap>", line 488, in _call_with_frames_removed
  File "C:\Users\Administrator\Desktop\Ticket\MUSEUM_BOT\ticket\urls.py", line 3, in <module>
    from . import views
  File "C:\Users\Administrator\Desktop\Ticket\MUSEUM_BOT\ticket\views.py", line 106
    if
      ^
SyntaxError: invalid syntax
C:\Users\Administrator\Desktop\Ticket\MUSEUM_BOT\ticket\views.py changed, reloading.
Watching for file changes with StatReloader
Performing system checks...

Exception in thread django-main-thread:
Traceback (most recent call last):
  File "C:\Users\Administrator\AppData\Local\Programs\Python\Python312\Lib\threading.py", line 1073, in _bootstrap_inner
    self.run()
  File "C:\Users\Administrator\AppData\Local\Programs\Python\Python312\Lib\threading.py", line 1010, in run
    self._target(*self._args, **self._kwargs)
  File "C:\Users\Administrator\AppData\Local\Programs\Python\Python312\Lib\site-packages\django\utils\autoreload.py", line 64, in wrapper
    fn(*args, **kwargs)
  File "C:\Users\Administrator\AppData\Local\Programs\Python\Python312\Lib\site-packages\django\core\management\commands\runserver.py", line 134, in inner_run
    self.check(display_num_errors=True)
  File "C:\Users\Administrator\AppData\Local\Programs\Python\Python312\Lib\site-packages\django\core\management\base.py", line 486, in check
    all_issues = checks.run_checks(
                 ^^^^^^^^^^^^^^^^^^
  File "C:\Users\Administrator\AppData\Local\Programs\Python\Python312\Lib\site-packages\django\core\checks\registry.py", line 88, in run_checks
    new_errors = check(app_configs=app_configs, databases=databases)
                 ^^^^^^^^^^^^^^^^^^^^^^^^^^^^^^^^^^^^^^^^^^^^^^^^^^^
  File "C:\Users\Administrator\AppData\Local\Programs\Python\Python312\Lib\site-packages\django\core\checks\urls.py", line 136, in check_custom_error_handlers
    handler = resolver.resolve_error_handler(status_code)
              ^^^^^^^^^^^^^^^^^^^^^^^^^^^^^^^^^^^^^^^^^^^
  File "C:\Users\Administrator\AppData\Local\Programs\Python\Python312\Lib\site-packages\django\urls\resolvers.py", line 732, in resolve_error_handler
    callback = getattr(self.urlconf_module, "handler%s" % view_type, None)
                       ^^^^^^^^^^^^^^^^^^^
  File "C:\Users\Administrator\AppData\Local\Programs\Python\Python312\Lib\site-packages\django\utils\functional.py", line 47, in __get__
    res = instance.__dict__[self.name] = self.func(instance)
                                         ^^^^^^^^^^^^^^^^^^^
  File "C:\Users\Administrator\AppData\Local\Programs\Python\Python312\Lib\site-packages\django\urls\resolvers.py", line 711, in urlconf_module
    return import_module(self.urlconf_name)
           ^^^^^^^^^^^^^^^^^^^^^^^^^^^^^^^^
  File "C:\Users\Administrator\AppData\Local\Programs\Python\Python312\Lib\importlib\__init__.py", line 90, in import_module
    return _bootstrap._gcd_import(name[level:], package, level)
           ^^^^^^^^^^^^^^^^^^^^^^^^^^^^^^^^^^^^^^^^^^^^^^^^^^^^
  File "<frozen importlib._bootstrap>", line 1387, in _gcd_import
  File "<frozen importlib._bootstrap>", line 1360, in _find_and_load
  File "<frozen importlib._bootstrap>", line 1331, in _find_and_load_unlocked
  File "<frozen importlib._bootstrap>", line 935, in _load_unlocked
  File "<frozen importlib._bootstrap_external>", line 995, in exec_module
  File "<frozen importlib._bootstrap>", line 488, in _call_with_frames_removed
  File "C:\Users\Administrator\Desktop\Ticket\MUSEUM_BOT\MUSEUM_BOT\urls.py", line 22, in <module>
    path('ticket/', include("ticket.urls"))
                    ^^^^^^^^^^^^^^^^^^^^^^
  File "C:\Users\Administrator\AppData\Local\Programs\Python\Python312\Lib\site-packages\django\urls\conf.py", line 39, in include
    urlconf_module = import_module(urlconf_module)
                     ^^^^^^^^^^^^^^^^^^^^^^^^^^^^^
  File "C:\Users\Administrator\AppData\Local\Programs\Python\Python312\Lib\importlib\__init__.py", line 90, in import_module
    return _bootstrap._gcd_import(name[level:], package, level)
           ^^^^^^^^^^^^^^^^^^^^^^^^^^^^^^^^^^^^^^^^^^^^^^^^^^^^
  File "<frozen importlib._bootstrap>", line 1387, in _gcd_import
  File "<frozen importlib._bootstrap>", line 1360, in _find_and_load
  File "<frozen importlib._bootstrap>", line 1331, in _find_and_load_unlocked
  File "<frozen importlib._bootstrap>", line 935, in _load_unlocked
  File "<frozen importlib._bootstrap_external>", line 995, in exec_module
  File "<frozen importlib._bootstrap>", line 488, in _call_with_frames_removed
  File "C:\Users\Administrator\Desktop\Ticket\MUSEUM_BOT\ticket\urls.py", line 3, in <module>
    from . import views
  File "C:\Users\Administrator\Desktop\Ticket\MUSEUM_BOT\ticket\views.py", line 107
    if type(response_json) == dict:
IndentationError: expected an indented block after 'if' statement on line 106
C:\Users\Administrator\Desktop\Ticket\MUSEUM_BOT\ticket\views.py changed, reloading.
Watching for file changes with StatReloader
Performing system checks...

Exception in thread django-main-thread:
Traceback (most recent call last):
  File "C:\Users\Administrator\AppData\Local\Programs\Python\Python312\Lib\threading.py", line 1073, in _bootstrap_inner
    self.run()
  File "C:\Users\Administrator\AppData\Local\Programs\Python\Python312\Lib\threading.py", line 1010, in run
    self._target(*self._args, **self._kwargs)
  File "C:\Users\Administrator\AppData\Local\Programs\Python\Python312\Lib\site-packages\django\utils\autoreload.py", line 64, in wrapper
    fn(*args, **kwargs)
  File "C:\Users\Administrator\AppData\Local\Programs\Python\Python312\Lib\site-packages\django\core\management\commands\runserver.py", line 134, in inner_run
    self.check(display_num_errors=True)
  File "C:\Users\Administrator\AppData\Local\Programs\Python\Python312\Lib\site-packages\django\core\management\base.py", line 486, in check
    all_issues = checks.run_checks(
                 ^^^^^^^^^^^^^^^^^^
  File "C:\Users\Administrator\AppData\Local\Programs\Python\Python312\Lib\site-packages\django\core\checks\registry.py", line 88, in run_checks
    new_errors = check(app_configs=app_configs, databases=databases)
                 ^^^^^^^^^^^^^^^^^^^^^^^^^^^^^^^^^^^^^^^^^^^^^^^^^^^
  File "C:\Users\Administrator\AppData\Local\Programs\Python\Python312\Lib\site-packages\django\core\checks\urls.py", line 136, in check_custom_error_handlers
    handler = resolver.resolve_error_handler(status_code)
              ^^^^^^^^^^^^^^^^^^^^^^^^^^^^^^^^^^^^^^^^^^^
  File "C:\Users\Administrator\AppData\Local\Programs\Python\Python312\Lib\site-packages\django\urls\resolvers.py", line 732, in resolve_error_handler
    callback = getattr(self.urlconf_module, "handler%s" % view_type, None)
                       ^^^^^^^^^^^^^^^^^^^
  File "C:\Users\Administrator\AppData\Local\Programs\Python\Python312\Lib\site-packages\django\utils\functional.py", line 47, in __get__
    res = instance.__dict__[self.name] = self.func(instance)
                                         ^^^^^^^^^^^^^^^^^^^
  File "C:\Users\Administrator\AppData\Local\Programs\Python\Python312\Lib\site-packages\django\urls\resolvers.py", line 711, in urlconf_module
    return import_module(self.urlconf_name)
           ^^^^^^^^^^^^^^^^^^^^^^^^^^^^^^^^
  File "C:\Users\Administrator\AppData\Local\Programs\Python\Python312\Lib\importlib\__init__.py", line 90, in import_module
    return _bootstrap._gcd_import(name[level:], package, level)
           ^^^^^^^^^^^^^^^^^^^^^^^^^^^^^^^^^^^^^^^^^^^^^^^^^^^^
  File "<frozen importlib._bootstrap>", line 1387, in _gcd_import
  File "<frozen importlib._bootstrap>", line 1360, in _find_and_load
  File "<frozen importlib._bootstrap>", line 1331, in _find_and_load_unlocked
  File "<frozen importlib._bootstrap>", line 935, in _load_unlocked
  File "<frozen importlib._bootstrap_external>", line 995, in exec_module
  File "<frozen importlib._bootstrap>", line 488, in _call_with_frames_removed
  File "C:\Users\Administrator\Desktop\Ticket\MUSEUM_BOT\MUSEUM_BOT\urls.py", line 22, in <module>
    path('ticket/', include("ticket.urls"))
                    ^^^^^^^^^^^^^^^^^^^^^^
  File "C:\Users\Administrator\AppData\Local\Programs\Python\Python312\Lib\site-packages\django\urls\conf.py", line 39, in include
    urlconf_module = import_module(urlconf_module)
                     ^^^^^^^^^^^^^^^^^^^^^^^^^^^^^
  File "C:\Users\Administrator\AppData\Local\Programs\Python\Python312\Lib\importlib\__init__.py", line 90, in import_module
    return _bootstrap._gcd_import(name[level:], package, level)
           ^^^^^^^^^^^^^^^^^^^^^^^^^^^^^^^^^^^^^^^^^^^^^^^^^^^^
  File "<frozen importlib._bootstrap>", line 1387, in _gcd_import
  File "<frozen importlib._bootstrap>", line 1360, in _find_and_load
  File "<frozen importlib._bootstrap>", line 1331, in _find_and_load_unlocked
  File "<frozen importlib._bootstrap>", line 935, in _load_unlocked
  File "<frozen importlib._bootstrap_external>", line 995, in exec_module
  File "<frozen importlib._bootstrap>", line 488, in _call_with_frames_removed
  File "C:\Users\Administrator\Desktop\Ticket\MUSEUM_BOT\ticket\urls.py", line 3, in <module>
    from . import views
  File "C:\Users\Administrator\Desktop\Ticket\MUSEUM_BOT\ticket\views.py", line 107
    if type(response_json) == dict:
IndentationError: expected an indented block after 'if' statement on line 106
C:\Users\Administrator\Desktop\Ticket\MUSEUM_BOT\ticket\views.py changed, reloading.
Watching for file changes with StatReloader
Performing system checks...

Exception in thread django-main-thread:
Traceback (most recent call last):
  File "C:\Users\Administrator\AppData\Local\Programs\Python\Python312\Lib\threading.py", line 1073, in _bootstrap_inner
    self.run()
  File "C:\Users\Administrator\AppData\Local\Programs\Python\Python312\Lib\threading.py", line 1010, in run
    self._target(*self._args, **self._kwargs)
  File "C:\Users\Administrator\AppData\Local\Programs\Python\Python312\Lib\site-packages\django\utils\autoreload.py", line 64, in wrapper
    fn(*args, **kwargs)
  File "C:\Users\Administrator\AppData\Local\Programs\Python\Python312\Lib\site-packages\django\core\management\commands\runserver.py", line 134, in inner_run
    self.check(display_num_errors=True)
  File "C:\Users\Administrator\AppData\Local\Programs\Python\Python312\Lib\site-packages\django\core\management\base.py", line 486, in check
    all_issues = checks.run_checks(
                 ^^^^^^^^^^^^^^^^^^
  File "C:\Users\Administrator\AppData\Local\Programs\Python\Python312\Lib\site-packages\django\core\checks\registry.py", line 88, in run_checks
    new_errors = check(app_configs=app_configs, databases=databases)
                 ^^^^^^^^^^^^^^^^^^^^^^^^^^^^^^^^^^^^^^^^^^^^^^^^^^^
  File "C:\Users\Administrator\AppData\Local\Programs\Python\Python312\Lib\site-packages\django\core\checks\urls.py", line 136, in check_custom_error_handlers
    handler = resolver.resolve_error_handler(status_code)
              ^^^^^^^^^^^^^^^^^^^^^^^^^^^^^^^^^^^^^^^^^^^
  File "C:\Users\Administrator\AppData\Local\Programs\Python\Python312\Lib\site-packages\django\urls\resolvers.py", line 732, in resolve_error_handler
    callback = getattr(self.urlconf_module, "handler%s" % view_type, None)
                       ^^^^^^^^^^^^^^^^^^^
  File "C:\Users\Administrator\AppData\Local\Programs\Python\Python312\Lib\site-packages\django\utils\functional.py", line 47, in __get__
    res = instance.__dict__[self.name] = self.func(instance)
                                         ^^^^^^^^^^^^^^^^^^^
  File "C:\Users\Administrator\AppData\Local\Programs\Python\Python312\Lib\site-packages\django\urls\resolvers.py", line 711, in urlconf_module
    return import_module(self.urlconf_name)
           ^^^^^^^^^^^^^^^^^^^^^^^^^^^^^^^^
  File "C:\Users\Administrator\AppData\Local\Programs\Python\Python312\Lib\importlib\__init__.py", line 90, in import_module
    return _bootstrap._gcd_import(name[level:], package, level)
           ^^^^^^^^^^^^^^^^^^^^^^^^^^^^^^^^^^^^^^^^^^^^^^^^^^^^
  File "<frozen importlib._bootstrap>", line 1387, in _gcd_import
  File "<frozen importlib._bootstrap>", line 1360, in _find_and_load
  File "<frozen importlib._bootstrap>", line 1331, in _find_and_load_unlocked
  File "<frozen importlib._bootstrap>", line 935, in _load_unlocked
  File "<frozen importlib._bootstrap_external>", line 995, in exec_module
  File "<frozen importlib._bootstrap>", line 488, in _call_with_frames_removed
  File "C:\Users\Administrator\Desktop\Ticket\MUSEUM_BOT\MUSEUM_BOT\urls.py", line 22, in <module>
    path('ticket/', include("ticket.urls"))
                    ^^^^^^^^^^^^^^^^^^^^^^
  File "C:\Users\Administrator\AppData\Local\Programs\Python\Python312\Lib\site-packages\django\urls\conf.py", line 39, in include
    urlconf_module = import_module(urlconf_module)
                     ^^^^^^^^^^^^^^^^^^^^^^^^^^^^^
  File "C:\Users\Administrator\AppData\Local\Programs\Python\Python312\Lib\importlib\__init__.py", line 90, in import_module
    return _bootstrap._gcd_import(name[level:], package, level)
           ^^^^^^^^^^^^^^^^^^^^^^^^^^^^^^^^^^^^^^^^^^^^^^^^^^^^
  File "<frozen importlib._bootstrap>", line 1387, in _gcd_import
  File "<frozen importlib._bootstrap>", line 1360, in _find_and_load
  File "<frozen importlib._bootstrap>", line 1331, in _find_and_load_unlocked
  File "<frozen importlib._bootstrap>", line 935, in _load_unlocked
  File "<frozen importlib._bootstrap_external>", line 995, in exec_module
  File "<frozen importlib._bootstrap>", line 488, in _call_with_frames_removed
  File "C:\Users\Administrator\Desktop\Ticket\MUSEUM_BOT\ticket\urls.py", line 3, in <module>
    from . import views
  File "C:\Users\Administrator\Desktop\Ticket\MUSEUM_BOT\ticket\views.py", line 107
    running =
              ^
SyntaxError: invalid syntax
C:\Users\Administrator\Desktop\Ticket\MUSEUM_BOT\ticket\views.py changed, reloading.
Watching for file changes with StatReloader
Performing system checks...

Exception in thread django-main-thread:
Traceback (most recent call last):
  File "C:\Users\Administrator\AppData\Local\Programs\Python\Python312\Lib\threading.py", line 1073, in _bootstrap_inner
    self.run()
  File "C:\Users\Administrator\AppData\Local\Programs\Python\Python312\Lib\threading.py", line 1010, in run
    self._target(*self._args, **self._kwargs)
  File "C:\Users\Administrator\AppData\Local\Programs\Python\Python312\Lib\site-packages\django\utils\autoreload.py", line 64, in wrapper
    fn(*args, **kwargs)
  File "C:\Users\Administrator\AppData\Local\Programs\Python\Python312\Lib\site-packages\django\core\management\commands\runserver.py", line 134, in inner_run
    self.check(display_num_errors=True)
  File "C:\Users\Administrator\AppData\Local\Programs\Python\Python312\Lib\site-packages\django\core\management\base.py", line 486, in check
    all_issues = checks.run_checks(
                 ^^^^^^^^^^^^^^^^^^
  File "C:\Users\Administrator\AppData\Local\Programs\Python\Python312\Lib\site-packages\django\core\checks\registry.py", line 88, in run_checks
    new_errors = check(app_configs=app_configs, databases=databases)
                 ^^^^^^^^^^^^^^^^^^^^^^^^^^^^^^^^^^^^^^^^^^^^^^^^^^^
  File "C:\Users\Administrator\AppData\Local\Programs\Python\Python312\Lib\site-packages\django\core\checks\urls.py", line 136, in check_custom_error_handlers
    handler = resolver.resolve_error_handler(status_code)
              ^^^^^^^^^^^^^^^^^^^^^^^^^^^^^^^^^^^^^^^^^^^
  File "C:\Users\Administrator\AppData\Local\Programs\Python\Python312\Lib\site-packages\django\urls\resolvers.py", line 732, in resolve_error_handler
    callback = getattr(self.urlconf_module, "handler%s" % view_type, None)
                       ^^^^^^^^^^^^^^^^^^^
  File "C:\Users\Administrator\AppData\Local\Programs\Python\Python312\Lib\site-packages\django\utils\functional.py", line 47, in __get__
    res = instance.__dict__[self.name] = self.func(instance)
                                         ^^^^^^^^^^^^^^^^^^^
  File "C:\Users\Administrator\AppData\Local\Programs\Python\Python312\Lib\site-packages\django\urls\resolvers.py", line 711, in urlconf_module
    return import_module(self.urlconf_name)
           ^^^^^^^^^^^^^^^^^^^^^^^^^^^^^^^^
  File "C:\Users\Administrator\AppData\Local\Programs\Python\Python312\Lib\importlib\__init__.py", line 90, in import_module
    return _bootstrap._gcd_import(name[level:], package, level)
           ^^^^^^^^^^^^^^^^^^^^^^^^^^^^^^^^^^^^^^^^^^^^^^^^^^^^
  File "<frozen importlib._bootstrap>", line 1387, in _gcd_import
  File "<frozen importlib._bootstrap>", line 1360, in _find_and_load
  File "<frozen importlib._bootstrap>", line 1331, in _find_and_load_unlocked
  File "<frozen importlib._bootstrap>", line 935, in _load_unlocked
  File "<frozen importlib._bootstrap_external>", line 995, in exec_module
  File "<frozen importlib._bootstrap>", line 488, in _call_with_frames_removed
  File "C:\Users\Administrator\Desktop\Ticket\MUSEUM_BOT\MUSEUM_BOT\urls.py", line 22, in <module>
    path('ticket/', include("ticket.urls"))
                    ^^^^^^^^^^^^^^^^^^^^^^
  File "C:\Users\Administrator\AppData\Local\Programs\Python\Python312\Lib\site-packages\django\urls\conf.py", line 39, in include
    urlconf_module = import_module(urlconf_module)
                     ^^^^^^^^^^^^^^^^^^^^^^^^^^^^^
  File "C:\Users\Administrator\AppData\Local\Programs\Python\Python312\Lib\importlib\__init__.py", line 90, in import_module
    return _bootstrap._gcd_import(name[level:], package, level)
           ^^^^^^^^^^^^^^^^^^^^^^^^^^^^^^^^^^^^^^^^^^^^^^^^^^^^
  File "<frozen importlib._bootstrap>", line 1387, in _gcd_import
  File "<frozen importlib._bootstrap>", line 1360, in _find_and_load
  File "<frozen importlib._bootstrap>", line 1331, in _find_and_load_unlocked
  File "<frozen importlib._bootstrap>", line 935, in _load_unlocked
  File "<frozen importlib._bootstrap_external>", line 995, in exec_module
  File "<frozen importlib._bootstrap>", line 488, in _call_with_frames_removed
  File "C:\Users\Administrator\Desktop\Ticket\MUSEUM_BOT\ticket\urls.py", line 3, in <module>
    from . import views
  File "C:\Users\Administrator\Desktop\Ticket\MUSEUM_BOT\ticket\views.py", line 107
    running = False                    if type(response_json) == dict:
                                                                     ^
SyntaxError: invalid syntax
C:\Users\Administrator\Desktop\Ticket\MUSEUM_BOT\ticket\views.py changed, reloading.
Watching for file changes with StatReloader
Performing system checks...

Exception in thread django-main-thread:
Traceback (most recent call last):
  File "C:\Users\Administrator\AppData\Local\Programs\Python\Python312\Lib\threading.py", line 1073, in _bootstrap_inner
    self.run()
  File "C:\Users\Administrator\AppData\Local\Programs\Python\Python312\Lib\threading.py", line 1010, in run
    self._target(*self._args, **self._kwargs)
  File "C:\Users\Administrator\AppData\Local\Programs\Python\Python312\Lib\site-packages\django\utils\autoreload.py", line 64, in wrapper
    fn(*args, **kwargs)
  File "C:\Users\Administrator\AppData\Local\Programs\Python\Python312\Lib\site-packages\django\core\management\commands\runserver.py", line 134, in inner_run
    self.check(display_num_errors=True)
  File "C:\Users\Administrator\AppData\Local\Programs\Python\Python312\Lib\site-packages\django\core\management\base.py", line 486, in check
    all_issues = checks.run_checks(
                 ^^^^^^^^^^^^^^^^^^
  File "C:\Users\Administrator\AppData\Local\Programs\Python\Python312\Lib\site-packages\django\core\checks\registry.py", line 88, in run_checks
    new_errors = check(app_configs=app_configs, databases=databases)
                 ^^^^^^^^^^^^^^^^^^^^^^^^^^^^^^^^^^^^^^^^^^^^^^^^^^^
  File "C:\Users\Administrator\AppData\Local\Programs\Python\Python312\Lib\site-packages\django\core\checks\urls.py", line 136, in check_custom_error_handlers
    handler = resolver.resolve_error_handler(status_code)
              ^^^^^^^^^^^^^^^^^^^^^^^^^^^^^^^^^^^^^^^^^^^
  File "C:\Users\Administrator\AppData\Local\Programs\Python\Python312\Lib\site-packages\django\urls\resolvers.py", line 732, in resolve_error_handler
    callback = getattr(self.urlconf_module, "handler%s" % view_type, None)
                       ^^^^^^^^^^^^^^^^^^^
  File "C:\Users\Administrator\AppData\Local\Programs\Python\Python312\Lib\site-packages\django\utils\functional.py", line 47, in __get__
    res = instance.__dict__[self.name] = self.func(instance)
                                         ^^^^^^^^^^^^^^^^^^^
  File "C:\Users\Administrator\AppData\Local\Programs\Python\Python312\Lib\site-packages\django\urls\resolvers.py", line 711, in urlconf_module
    return import_module(self.urlconf_name)
           ^^^^^^^^^^^^^^^^^^^^^^^^^^^^^^^^
  File "C:\Users\Administrator\AppData\Local\Programs\Python\Python312\Lib\importlib\__init__.py", line 90, in import_module
    return _bootstrap._gcd_import(name[level:], package, level)
           ^^^^^^^^^^^^^^^^^^^^^^^^^^^^^^^^^^^^^^^^^^^^^^^^^^^^
  File "<frozen importlib._bootstrap>", line 1387, in _gcd_import
  File "<frozen importlib._bootstrap>", line 1360, in _find_and_load
  File "<frozen importlib._bootstrap>", line 1331, in _find_and_load_unlocked
  File "<frozen importlib._bootstrap>", line 935, in _load_unlocked
  File "<frozen importlib._bootstrap_external>", line 995, in exec_module
  File "<frozen importlib._bootstrap>", line 488, in _call_with_frames_removed
  File "C:\Users\Administrator\Desktop\Ticket\MUSEUM_BOT\MUSEUM_BOT\urls.py", line 22, in <module>
    path('ticket/', include("ticket.urls"))
                    ^^^^^^^^^^^^^^^^^^^^^^
  File "C:\Users\Administrator\AppData\Local\Programs\Python\Python312\Lib\site-packages\django\urls\conf.py", line 39, in include
    urlconf_module = import_module(urlconf_module)
                     ^^^^^^^^^^^^^^^^^^^^^^^^^^^^^
  File "C:\Users\Administrator\AppData\Local\Programs\Python\Python312\Lib\importlib\__init__.py", line 90, in import_module
    return _bootstrap._gcd_import(name[level:], package, level)
           ^^^^^^^^^^^^^^^^^^^^^^^^^^^^^^^^^^^^^^^^^^^^^^^^^^^^
  File "<frozen importlib._bootstrap>", line 1387, in _gcd_import
  File "<frozen importlib._bootstrap>", line 1360, in _find_and_load
  File "<frozen importlib._bootstrap>", line 1331, in _find_and_load_unlocked
  File "<frozen importlib._bootstrap>", line 935, in _load_unlocked
  File "<frozen importlib._bootstrap_external>", line 995, in exec_module
  File "<frozen importlib._bootstrap>", line 488, in _call_with_frames_removed
  File "C:\Users\Administrator\Desktop\Ticket\MUSEUM_BOT\ticket\urls.py", line 3, in <module>
    from . import views
  File "C:\Users\Administrator\Desktop\Ticket\MUSEUM_BOT\ticket\views.py", line 107
    running = False                    if type(response_json) == dict:
                                                                     ^
SyntaxError: invalid syntax
C:\Users\Administrator\Desktop\Ticket\MUSEUM_BOT\ticket\views.py changed, reloading.
Watching for file changes with StatReloader
Performing system checks...

Exception in thread django-main-thread:
Traceback (most recent call last):
  File "C:\Users\Administrator\AppData\Local\Programs\Python\Python312\Lib\threading.py", line 1073, in _bootstrap_inner
    self.run()
  File "C:\Users\Administrator\AppData\Local\Programs\Python\Python312\Lib\threading.py", line 1010, in run
    self._target(*self._args, **self._kwargs)
  File "C:\Users\Administrator\AppData\Local\Programs\Python\Python312\Lib\site-packages\django\utils\autoreload.py", line 64, in wrapper
    fn(*args, **kwargs)
  File "C:\Users\Administrator\AppData\Local\Programs\Python\Python312\Lib\site-packages\django\core\management\commands\runserver.py", line 134, in inner_run
    self.check(display_num_errors=True)
  File "C:\Users\Administrator\AppData\Local\Programs\Python\Python312\Lib\site-packages\django\core\management\base.py", line 486, in check
    all_issues = checks.run_checks(
                 ^^^^^^^^^^^^^^^^^^
  File "C:\Users\Administrator\AppData\Local\Programs\Python\Python312\Lib\site-packages\django\core\checks\registry.py", line 88, in run_checks
    new_errors = check(app_configs=app_configs, databases=databases)
                 ^^^^^^^^^^^^^^^^^^^^^^^^^^^^^^^^^^^^^^^^^^^^^^^^^^^
  File "C:\Users\Administrator\AppData\Local\Programs\Python\Python312\Lib\site-packages\django\core\checks\urls.py", line 136, in check_custom_error_handlers
    handler = resolver.resolve_error_handler(status_code)
              ^^^^^^^^^^^^^^^^^^^^^^^^^^^^^^^^^^^^^^^^^^^
  File "C:\Users\Administrator\AppData\Local\Programs\Python\Python312\Lib\site-packages\django\urls\resolvers.py", line 732, in resolve_error_handler
    callback = getattr(self.urlconf_module, "handler%s" % view_type, None)
                       ^^^^^^^^^^^^^^^^^^^
  File "C:\Users\Administrator\AppData\Local\Programs\Python\Python312\Lib\site-packages\django\utils\functional.py", line 47, in __get__
    res = instance.__dict__[self.name] = self.func(instance)
                                         ^^^^^^^^^^^^^^^^^^^
  File "C:\Users\Administrator\AppData\Local\Programs\Python\Python312\Lib\site-packages\django\urls\resolvers.py", line 711, in urlconf_module
    return import_module(self.urlconf_name)
           ^^^^^^^^^^^^^^^^^^^^^^^^^^^^^^^^
  File "C:\Users\Administrator\AppData\Local\Programs\Python\Python312\Lib\importlib\__init__.py", line 90, in import_module
    return _bootstrap._gcd_import(name[level:], package, level)
           ^^^^^^^^^^^^^^^^^^^^^^^^^^^^^^^^^^^^^^^^^^^^^^^^^^^^
  File "<frozen importlib._bootstrap>", line 1387, in _gcd_import
  File "<frozen importlib._bootstrap>", line 1360, in _find_and_load
  File "<frozen importlib._bootstrap>", line 1331, in _find_and_load_unlocked
  File "<frozen importlib._bootstrap>", line 935, in _load_unlocked
  File "<frozen importlib._bootstrap_external>", line 995, in exec_module
  File "<frozen importlib._bootstrap>", line 488, in _call_with_frames_removed
  File "C:\Users\Administrator\Desktop\Ticket\MUSEUM_BOT\MUSEUM_BOT\urls.py", line 22, in <module>
    path('ticket/', include("ticket.urls"))
                    ^^^^^^^^^^^^^^^^^^^^^^
  File "C:\Users\Administrator\AppData\Local\Programs\Python\Python312\Lib\site-packages\django\urls\conf.py", line 39, in include
    urlconf_module = import_module(urlconf_module)
                     ^^^^^^^^^^^^^^^^^^^^^^^^^^^^^
  File "C:\Users\Administrator\AppData\Local\Programs\Python\Python312\Lib\importlib\__init__.py", line 90, in import_module
    return _bootstrap._gcd_import(name[level:], package, level)
           ^^^^^^^^^^^^^^^^^^^^^^^^^^^^^^^^^^^^^^^^^^^^^^^^^^^^
  File "<frozen importlib._bootstrap>", line 1387, in _gcd_import
  File "<frozen importlib._bootstrap>", line 1360, in _find_and_load
  File "<frozen importlib._bootstrap>", line 1331, in _find_and_load_unlocked
  File "<frozen importlib._bootstrap>", line 935, in _load_unlocked
  File "<frozen importlib._bootstrap_external>", line 995, in exec_module
  File "<frozen importlib._bootstrap>", line 488, in _call_with_frames_removed
  File "C:\Users\Administrator\Desktop\Ticket\MUSEUM_BOT\ticket\urls.py", line 3, in <module>
    from . import views
  File "C:\Users\Administrator\Desktop\Ticket\MUSEUM_BOT\ticket\views.py", line 109
    response_json = normalize_json_structure(response_json)
                                                           ^
IndentationError: unindent does not match any outer indentation level
C:\Users\Administrator\Desktop\Ticket\MUSEUM_BOT\ticket\views.py changed, reloading.
Watching for file changes with StatReloader
Performing system checks...

Exception in thread django-main-thread:
Traceback (most recent call last):
  File "C:\Users\Administrator\AppData\Local\Programs\Python\Python312\Lib\threading.py", line 1073, in _bootstrap_inner
    self.run()
  File "C:\Users\Administrator\AppData\Local\Programs\Python\Python312\Lib\threading.py", line 1010, in run
    self._target(*self._args, **self._kwargs)
  File "C:\Users\Administrator\AppData\Local\Programs\Python\Python312\Lib\site-packages\django\utils\autoreload.py", line 64, in wrapper
    fn(*args, **kwargs)
  File "C:\Users\Administrator\AppData\Local\Programs\Python\Python312\Lib\site-packages\django\core\management\commands\runserver.py", line 134, in inner_run
    self.check(display_num_errors=True)
  File "C:\Users\Administrator\AppData\Local\Programs\Python\Python312\Lib\site-packages\django\core\management\base.py", line 486, in check
    all_issues = checks.run_checks(
                 ^^^^^^^^^^^^^^^^^^
  File "C:\Users\Administrator\AppData\Local\Programs\Python\Python312\Lib\site-packages\django\core\checks\registry.py", line 88, in run_checks
    new_errors = check(app_configs=app_configs, databases=databases)
                 ^^^^^^^^^^^^^^^^^^^^^^^^^^^^^^^^^^^^^^^^^^^^^^^^^^^
  File "C:\Users\Administrator\AppData\Local\Programs\Python\Python312\Lib\site-packages\django\core\checks\urls.py", line 136, in check_custom_error_handlers
    handler = resolver.resolve_error_handler(status_code)
              ^^^^^^^^^^^^^^^^^^^^^^^^^^^^^^^^^^^^^^^^^^^
  File "C:\Users\Administrator\AppData\Local\Programs\Python\Python312\Lib\site-packages\django\urls\resolvers.py", line 732, in resolve_error_handler
    callback = getattr(self.urlconf_module, "handler%s" % view_type, None)
                       ^^^^^^^^^^^^^^^^^^^
  File "C:\Users\Administrator\AppData\Local\Programs\Python\Python312\Lib\site-packages\django\utils\functional.py", line 47, in __get__
    res = instance.__dict__[self.name] = self.func(instance)
                                         ^^^^^^^^^^^^^^^^^^^
  File "C:\Users\Administrator\AppData\Local\Programs\Python\Python312\Lib\site-packages\django\urls\resolvers.py", line 711, in urlconf_module
    return import_module(self.urlconf_name)
           ^^^^^^^^^^^^^^^^^^^^^^^^^^^^^^^^
  File "C:\Users\Administrator\AppData\Local\Programs\Python\Python312\Lib\importlib\__init__.py", line 90, in import_module
    return _bootstrap._gcd_import(name[level:], package, level)
           ^^^^^^^^^^^^^^^^^^^^^^^^^^^^^^^^^^^^^^^^^^^^^^^^^^^^
  File "<frozen importlib._bootstrap>", line 1387, in _gcd_import
  File "<frozen importlib._bootstrap>", line 1360, in _find_and_load
  File "<frozen importlib._bootstrap>", line 1331, in _find_and_load_unlocked
  File "<frozen importlib._bootstrap>", line 935, in _load_unlocked
  File "<frozen importlib._bootstrap_external>", line 995, in exec_module
  File "<frozen importlib._bootstrap>", line 488, in _call_with_frames_removed
  File "C:\Users\Administrator\Desktop\Ticket\MUSEUM_BOT\MUSEUM_BOT\urls.py", line 22, in <module>
    path('ticket/', include("ticket.urls"))
                    ^^^^^^^^^^^^^^^^^^^^^^
  File "C:\Users\Administrator\AppData\Local\Programs\Python\Python312\Lib\site-packages\django\urls\conf.py", line 39, in include
    urlconf_module = import_module(urlconf_module)
                     ^^^^^^^^^^^^^^^^^^^^^^^^^^^^^
  File "C:\Users\Administrator\AppData\Local\Programs\Python\Python312\Lib\importlib\__init__.py", line 90, in import_module
    return _bootstrap._gcd_import(name[level:], package, level)
           ^^^^^^^^^^^^^^^^^^^^^^^^^^^^^^^^^^^^^^^^^^^^^^^^^^^^
  File "<frozen importlib._bootstrap>", line 1387, in _gcd_import
  File "<frozen importlib._bootstrap>", line 1360, in _find_and_load
  File "<frozen importlib._bootstrap>", line 1331, in _find_and_load_unlocked
  File "<frozen importlib._bootstrap>", line 935, in _load_unlocked
  File "<frozen importlib._bootstrap_external>", line 995, in exec_module
  File "<frozen importlib._bootstrap>", line 488, in _call_with_frames_removed
  File "C:\Users\Administrator\Desktop\Ticket\MUSEUM_BOT\ticket\urls.py", line 3, in <module>
    from . import views
  File "C:\Users\Administrator\Desktop\Ticket\MUSEUM_BOT\ticket\views.py", line 109
    response_json = normalize_json_structure(response_json)
                                                           ^
IndentationError: unindent does not match any outer indentation level
C:\Users\Administrator\Desktop\Ticket\MUSEUM_BOT\ticket\views.py changed, reloading.
Watching for file changes with StatReloader
Performing system checks...

Exception in thread django-main-thread:
Traceback (most recent call last):
  File "C:\Users\Administrator\AppData\Local\Programs\Python\Python312\Lib\threading.py", line 1073, in _bootstrap_inner
    self.run()
  File "C:\Users\Administrator\AppData\Local\Programs\Python\Python312\Lib\threading.py", line 1010, in run
    self._target(*self._args, **self._kwargs)
  File "C:\Users\Administrator\AppData\Local\Programs\Python\Python312\Lib\site-packages\django\utils\autoreload.py", line 64, in wrapper
    fn(*args, **kwargs)
  File "C:\Users\Administrator\AppData\Local\Programs\Python\Python312\Lib\site-packages\django\core\management\commands\runserver.py", line 134, in inner_run
    self.check(display_num_errors=True)
  File "C:\Users\Administrator\AppData\Local\Programs\Python\Python312\Lib\site-packages\django\core\management\base.py", line 486, in check
    all_issues = checks.run_checks(
                 ^^^^^^^^^^^^^^^^^^
  File "C:\Users\Administrator\AppData\Local\Programs\Python\Python312\Lib\site-packages\django\core\checks\registry.py", line 88, in run_checks
    new_errors = check(app_configs=app_configs, databases=databases)
                 ^^^^^^^^^^^^^^^^^^^^^^^^^^^^^^^^^^^^^^^^^^^^^^^^^^^
  File "C:\Users\Administrator\AppData\Local\Programs\Python\Python312\Lib\site-packages\django\core\checks\urls.py", line 136, in check_custom_error_handlers
    handler = resolver.resolve_error_handler(status_code)
              ^^^^^^^^^^^^^^^^^^^^^^^^^^^^^^^^^^^^^^^^^^^
  File "C:\Users\Administrator\AppData\Local\Programs\Python\Python312\Lib\site-packages\django\urls\resolvers.py", line 732, in resolve_error_handler
    callback = getattr(self.urlconf_module, "handler%s" % view_type, None)
                       ^^^^^^^^^^^^^^^^^^^
  File "C:\Users\Administrator\AppData\Local\Programs\Python\Python312\Lib\site-packages\django\utils\functional.py", line 47, in __get__
    res = instance.__dict__[self.name] = self.func(instance)
                                         ^^^^^^^^^^^^^^^^^^^
  File "C:\Users\Administrator\AppData\Local\Programs\Python\Python312\Lib\site-packages\django\urls\resolvers.py", line 711, in urlconf_module
    return import_module(self.urlconf_name)
           ^^^^^^^^^^^^^^^^^^^^^^^^^^^^^^^^
  File "C:\Users\Administrator\AppData\Local\Programs\Python\Python312\Lib\importlib\__init__.py", line 90, in import_module
    return _bootstrap._gcd_import(name[level:], package, level)
           ^^^^^^^^^^^^^^^^^^^^^^^^^^^^^^^^^^^^^^^^^^^^^^^^^^^^
  File "<frozen importlib._bootstrap>", line 1387, in _gcd_import
  File "<frozen importlib._bootstrap>", line 1360, in _find_and_load
  File "<frozen importlib._bootstrap>", line 1331, in _find_and_load_unlocked
  File "<frozen importlib._bootstrap>", line 935, in _load_unlocked
  File "<frozen importlib._bootstrap_external>", line 995, in exec_module
  File "<frozen importlib._bootstrap>", line 488, in _call_with_frames_removed
  File "C:\Users\Administrator\Desktop\Ticket\MUSEUM_BOT\MUSEUM_BOT\urls.py", line 22, in <module>
    path('ticket/', include("ticket.urls"))
                    ^^^^^^^^^^^^^^^^^^^^^^
  File "C:\Users\Administrator\AppData\Local\Programs\Python\Python312\Lib\site-packages\django\urls\conf.py", line 39, in include
    urlconf_module = import_module(urlconf_module)
                     ^^^^^^^^^^^^^^^^^^^^^^^^^^^^^
  File "C:\Users\Administrator\AppData\Local\Programs\Python\Python312\Lib\importlib\__init__.py", line 90, in import_module
    return _bootstrap._gcd_import(name[level:], package, level)
           ^^^^^^^^^^^^^^^^^^^^^^^^^^^^^^^^^^^^^^^^^^^^^^^^^^^^
  File "<frozen importlib._bootstrap>", line 1387, in _gcd_import
  File "<frozen importlib._bootstrap>", line 1360, in _find_and_load
  File "<frozen importlib._bootstrap>", line 1331, in _find_and_load_unlocked
  File "<frozen importlib._bootstrap>", line 935, in _load_unlocked
  File "<frozen importlib._bootstrap_external>", line 995, in exec_module
  File "<frozen importlib._bootstrap>", line 488, in _call_with_frames_removed
  File "C:\Users\Administrator\Desktop\Ticket\MUSEUM_BOT\ticket\urls.py", line 3, in <module>
    from . import views
  File "C:\Users\Administrator\Desktop\Ticket\MUSEUM_BOT\ticket\views.py", line 109
    response_json = normalize_json_structure(response_json)
                                                           ^
IndentationError: unindent does not match any outer indentation level
C:\Users\Administrator\Desktop\Ticket\MUSEUM_BOT\ticket\views.py changed, reloading.
Watching for file changes with StatReloader
Performing system checks...

Exception in thread django-main-thread:
Traceback (most recent call last):
  File "C:\Users\Administrator\AppData\Local\Programs\Python\Python312\Lib\threading.py", line 1073, in _bootstrap_inner
    self.run()
  File "C:\Users\Administrator\AppData\Local\Programs\Python\Python312\Lib\threading.py", line 1010, in run
    self._target(*self._args, **self._kwargs)
  File "C:\Users\Administrator\AppData\Local\Programs\Python\Python312\Lib\site-packages\django\utils\autoreload.py", line 64, in wrapper
    fn(*args, **kwargs)
  File "C:\Users\Administrator\AppData\Local\Programs\Python\Python312\Lib\site-packages\django\core\management\commands\runserver.py", line 134, in inner_run
    self.check(display_num_errors=True)
  File "C:\Users\Administrator\AppData\Local\Programs\Python\Python312\Lib\site-packages\django\core\management\base.py", line 486, in check
    all_issues = checks.run_checks(
                 ^^^^^^^^^^^^^^^^^^
  File "C:\Users\Administrator\AppData\Local\Programs\Python\Python312\Lib\site-packages\django\core\checks\registry.py", line 88, in run_checks
    new_errors = check(app_configs=app_configs, databases=databases)
                 ^^^^^^^^^^^^^^^^^^^^^^^^^^^^^^^^^^^^^^^^^^^^^^^^^^^
  File "C:\Users\Administrator\AppData\Local\Programs\Python\Python312\Lib\site-packages\django\core\checks\urls.py", line 136, in check_custom_error_handlers
    handler = resolver.resolve_error_handler(status_code)
              ^^^^^^^^^^^^^^^^^^^^^^^^^^^^^^^^^^^^^^^^^^^
  File "C:\Users\Administrator\AppData\Local\Programs\Python\Python312\Lib\site-packages\django\urls\resolvers.py", line 732, in resolve_error_handler
    callback = getattr(self.urlconf_module, "handler%s" % view_type, None)
                       ^^^^^^^^^^^^^^^^^^^
  File "C:\Users\Administrator\AppData\Local\Programs\Python\Python312\Lib\site-packages\django\utils\functional.py", line 47, in __get__
    res = instance.__dict__[self.name] = self.func(instance)
                                         ^^^^^^^^^^^^^^^^^^^
  File "C:\Users\Administrator\AppData\Local\Programs\Python\Python312\Lib\site-packages\django\urls\resolvers.py", line 711, in urlconf_module
    return import_module(self.urlconf_name)
           ^^^^^^^^^^^^^^^^^^^^^^^^^^^^^^^^
  File "C:\Users\Administrator\AppData\Local\Programs\Python\Python312\Lib\importlib\__init__.py", line 90, in import_module
    return _bootstrap._gcd_import(name[level:], package, level)
           ^^^^^^^^^^^^^^^^^^^^^^^^^^^^^^^^^^^^^^^^^^^^^^^^^^^^
  File "<frozen importlib._bootstrap>", line 1387, in _gcd_import
  File "<frozen importlib._bootstrap>", line 1360, in _find_and_load
  File "<frozen importlib._bootstrap>", line 1331, in _find_and_load_unlocked
  File "<frozen importlib._bootstrap>", line 935, in _load_unlocked
  File "<frozen importlib._bootstrap_external>", line 995, in exec_module
  File "<frozen importlib._bootstrap>", line 488, in _call_with_frames_removed
  File "C:\Users\Administrator\Desktop\Ticket\MUSEUM_BOT\MUSEUM_BOT\urls.py", line 22, in <module>
    path('ticket/', include("ticket.urls"))
                    ^^^^^^^^^^^^^^^^^^^^^^
  File "C:\Users\Administrator\AppData\Local\Programs\Python\Python312\Lib\site-packages\django\urls\conf.py", line 39, in include
    urlconf_module = import_module(urlconf_module)
                     ^^^^^^^^^^^^^^^^^^^^^^^^^^^^^
  File "C:\Users\Administrator\AppData\Local\Programs\Python\Python312\Lib\importlib\__init__.py", line 90, in import_module
    return _bootstrap._gcd_import(name[level:], package, level)
           ^^^^^^^^^^^^^^^^^^^^^^^^^^^^^^^^^^^^^^^^^^^^^^^^^^^^
  File "<frozen importlib._bootstrap>", line 1387, in _gcd_import
  File "<frozen importlib._bootstrap>", line 1360, in _find_and_load
  File "<frozen importlib._bootstrap>", line 1331, in _find_and_load_unlocked
  File "<frozen importlib._bootstrap>", line 935, in _load_unlocked
  File "<frozen importlib._bootstrap_external>", line 995, in exec_module
  File "<frozen importlib._bootstrap>", line 488, in _call_with_frames_removed
  File "C:\Users\Administrator\Desktop\Ticket\MUSEUM_BOT\ticket\urls.py", line 3, in <module>
    from . import views
  File "C:\Users\Administrator\Desktop\Ticket\MUSEUM_BOT\ticket\views.py", line 108
    if type(response_json) == dict:
                                   ^
IndentationError: unindent does not match any outer indentation level
C:\Users\Administrator\Desktop\Ticket\MUSEUM_BOT\ticket\views.py changed, reloading.
Watching for file changes with StatReloader
Performing system checks...

System check identified no issues (0 silenced).
August 23, 2024 - 13:12:34
Django version 5.1, using settings 'MUSEUM_BOT.settings'
Starting development server at http://127.0.0.1:6969/
Quit the server with CTRL-BREAK.

<class 'str'>
user : give me json in {} not in [{}]
ai json : {"users": [{"user_info": {"name": null, "age": null, "indian": null, "student": null, "ticket_type": null, "day": null, "month": null, "year": null}}], "your_response_back_to_user": "Hello there! 👋  Welcome to Albert Hall Museum booking,  Let's get you some tickets!  How many tickets are you looking for?  To begin, tell me your name.", "confirm": false}    

Dict Detected
C:\Users\Administrator\Desktop\Ticket\MUSEUM_BOT\ticket\views.py changed, reloading.
Watching for file changes with StatReloader
Performing system checks...

Exception in thread django-main-thread:
Traceback (most recent call last):
  File "C:\Users\Administrator\AppData\Local\Programs\Python\Python312\Lib\threading.py", line 1073, in _bootstrap_inner
    self.run()
  File "C:\Users\Administrator\AppData\Local\Programs\Python\Python312\Lib\threading.py", line 1010, in run
    self._target(*self._args, **self._kwargs)
  File "C:\Users\Administrator\AppData\Local\Programs\Python\Python312\Lib\site-packages\django\utils\autoreload.py", line 64, in wrapper
    fn(*args, **kwargs)
  File "C:\Users\Administrator\AppData\Local\Programs\Python\Python312\Lib\site-packages\django\core\management\commands\runserver.py", line 134, in inner_run
    self.check(display_num_errors=True)
  File "C:\Users\Administrator\AppData\Local\Programs\Python\Python312\Lib\site-packages\django\core\management\base.py", line 486, in check
    all_issues = checks.run_checks(
                 ^^^^^^^^^^^^^^^^^^
  File "C:\Users\Administrator\AppData\Local\Programs\Python\Python312\Lib\site-packages\django\core\checks\registry.py", line 88, in run_checks
    new_errors = check(app_configs=app_configs, databases=databases)
                 ^^^^^^^^^^^^^^^^^^^^^^^^^^^^^^^^^^^^^^^^^^^^^^^^^^^
  File "C:\Users\Administrator\AppData\Local\Programs\Python\Python312\Lib\site-packages\django\core\checks\urls.py", line 136, in check_custom_error_handlers
    handler = resolver.resolve_error_handler(status_code)
              ^^^^^^^^^^^^^^^^^^^^^^^^^^^^^^^^^^^^^^^^^^^
  File "C:\Users\Administrator\AppData\Local\Programs\Python\Python312\Lib\site-packages\django\urls\resolvers.py", line 732, in resolve_error_handler
    callback = getattr(self.urlconf_module, "handler%s" % view_type, None)
                       ^^^^^^^^^^^^^^^^^^^
  File "C:\Users\Administrator\AppData\Local\Programs\Python\Python312\Lib\site-packages\django\utils\functional.py", line 47, in __get__
    res = instance.__dict__[self.name] = self.func(instance)
                                         ^^^^^^^^^^^^^^^^^^^
  File "C:\Users\Administrator\AppData\Local\Programs\Python\Python312\Lib\site-packages\django\urls\resolvers.py", line 711, in urlconf_module
    return import_module(self.urlconf_name)
           ^^^^^^^^^^^^^^^^^^^^^^^^^^^^^^^^
  File "C:\Users\Administrator\AppData\Local\Programs\Python\Python312\Lib\importlib\__init__.py", line 90, in import_module
    return _bootstrap._gcd_import(name[level:], package, level)
           ^^^^^^^^^^^^^^^^^^^^^^^^^^^^^^^^^^^^^^^^^^^^^^^^^^^^
  File "<frozen importlib._bootstrap>", line 1387, in _gcd_import
  File "<frozen importlib._bootstrap>", line 1360, in _find_and_load
  File "<frozen importlib._bootstrap>", line 1331, in _find_and_load_unlocked
  File "<frozen importlib._bootstrap>", line 935, in _load_unlocked
  File "<frozen importlib._bootstrap_external>", line 995, in exec_module
  File "<frozen importlib._bootstrap>", line 488, in _call_with_frames_removed
  File "C:\Users\Administrator\Desktop\Ticket\MUSEUM_BOT\MUSEUM_BOT\urls.py", line 22, in <module>
    path('ticket/', include("ticket.urls"))
                    ^^^^^^^^^^^^^^^^^^^^^^
  File "C:\Users\Administrator\AppData\Local\Programs\Python\Python312\Lib\site-packages\django\urls\conf.py", line 39, in include
    urlconf_module = import_module(urlconf_module)
                     ^^^^^^^^^^^^^^^^^^^^^^^^^^^^^
  File "C:\Users\Administrator\AppData\Local\Programs\Python\Python312\Lib\importlib\__init__.py", line 90, in import_module
    return _bootstrap._gcd_import(name[level:], package, level)
           ^^^^^^^^^^^^^^^^^^^^^^^^^^^^^^^^^^^^^^^^^^^^^^^^^^^^
  File "<frozen importlib._bootstrap>", line 1387, in _gcd_import
  File "<frozen importlib._bootstrap>", line 1360, in _find_and_load
  File "<frozen importlib._bootstrap>", line 1331, in _find_and_load_unlocked
  File "<frozen importlib._bootstrap>", line 935, in _load_unlocked
  File "<frozen importlib._bootstrap_external>", line 995, in exec_module
  File "<frozen importlib._bootstrap>", line 488, in _call_with_frames_removed
  File "C:\Users\Administrator\Desktop\Ticket\MUSEUM_BOT\ticket\urls.py", line 3, in <module>
    from . import views
  File "C:\Users\Administrator\Desktop\Ticket\MUSEUM_BOT\ticket\views.py", line 105
    response _json= send_message(f"system error invalid json fomate expect [{'data'}] recived {'data'}")
             ^^^^^
SyntaxError: invalid syntax
C:\Users\Administrator\Desktop\Ticket\MUSEUM_BOT\ticket\views.py changed, reloading.
Watching for file changes with StatReloader
Performing system checks...

System check identified no issues (0 silenced).
August 23, 2024 - 13:13:46
Django version 5.1, using settings 'MUSEUM_BOT.settings'
Starting development server at http://127.0.0.1:6969/
Quit the server with CTRL-BREAK.

C:\Users\Administrator\Desktop\Ticket\MUSEUM_BOT\ticket\views.py changed, reloading.
Watching for file changes with StatReloader
Performing system checks...

System check identified no issues (0 silenced).
August 23, 2024 - 13:13:50
Django version 5.1, using settings 'MUSEUM_BOT.settings'
Starting development server at http://127.0.0.1:6969/
Quit the server with CTRL-BREAK.

C:\Users\Administrator\Desktop\Ticket\MUSEUM_BOT\ticket\views.py changed, reloading.
Watching for file changes with StatReloader
Performing system checks...

System check identified no issues (0 silenced).
August 23, 2024 - 13:13:53
Django version 5.1, using settings 'MUSEUM_BOT.settings'
Starting development server at http://127.0.0.1:6969/
Quit the server with CTRL-BREAK.

<class 'str'>
user : give me json in {} not in [{}]
ai json : {"users": [{"user_info": {"name": null, "age": null, "indian": null, "student": null, "ticket_type": null, "day": null, "month": null, "year": null}}], "your_response_back_to_user": "Ok, how many tickets are you looking for? ", "confirm": false}

Dict Detected
Internal Server Error: /ticket/
Traceback (most recent call last):
  File "C:\Users\Administrator\AppData\Local\Programs\Python\Python312\Lib\site-packages\django\core\handlers\exception.py", line 55, in inner
    response = get_response(request)
               ^^^^^^^^^^^^^^^^^^^^^
  File "C:\Users\Administrator\AppData\Local\Programs\Python\Python312\Lib\site-packages\django\core\handlers\base.py", line 197, in _get_response
    response = wrapped_callback(request, *callback_args, **callback_kwargs)
               ^^^^^^^^^^^^^^^^^^^^^^^^^^^^^^^^^^^^^^^^^^^^^^^^^^^^^^^^^^^^
  File "C:\Users\Administrator\AppData\Local\Programs\Python\Python312\Lib\site-packages\django\contrib\auth\decorators.py", line 60, in _view_wrapper
    return view_func(request, *args, **kwargs)
           ^^^^^^^^^^^^^^^^^^^^^^^^^^^^^^^^^^^
  File "C:\Users\Administrator\Desktop\Ticket\MUSEUM_BOT\ticket\views.py", line 152, in index
    if response_json[0]["confirm"] == True:
       ~~~~~~~~~~~~~^^^
TypeError: 'GenerateContentResponse' object is not subscriptable
[23/Aug/2024 13:14:08] "POST /ticket/ HTTP/1.1" 500 75328
C:\Users\Administrator\Desktop\Ticket\MUSEUM_BOT\ticket\views.py changed, reloading.
Watching for file changes with StatReloader
Performing system checks...

System check identified no issues (0 silenced).
August 23, 2024 - 13:15:04
Django version 5.1, using settings 'MUSEUM_BOT.settings'
Starting development server at http://127.0.0.1:6969/
Quit the server with CTRL-BREAK.

C:\Users\Administrator\Desktop\Ticket\MUSEUM_BOT\ticket\views.py changed, reloading.
Watching for file changes with StatReloader
Performing system checks...

System check identified no issues (0 silenced).
August 23, 2024 - 13:15:11
Django version 5.1, using settings 'MUSEUM_BOT.settings'
Starting development server at http://127.0.0.1:6969/
Quit the server with CTRL-BREAK.

C:\Users\Administrator\Desktop\Ticket\MUSEUM_BOT\ticket\views.py changed, reloading.
Watching for file changes with StatReloader
Performing system checks...

Exception in thread django-main-thread:
Traceback (most recent call last):
  File "C:\Users\Administrator\AppData\Local\Programs\Python\Python312\Lib\threading.py", line 1073, in _bootstrap_inner
    self.run()
  File "C:\Users\Administrator\AppData\Local\Programs\Python\Python312\Lib\threading.py", line 1010, in run
    self._target(*self._args, **self._kwargs)
  File "C:\Users\Administrator\AppData\Local\Programs\Python\Python312\Lib\site-packages\django\utils\autoreload.py", line 64, in wrapper
    fn(*args, **kwargs)
  File "C:\Users\Administrator\AppData\Local\Programs\Python\Python312\Lib\site-packages\django\core\management\commands\runserver.py", line 134, in inner_run
    self.check(display_num_errors=True)
  File "C:\Users\Administrator\AppData\Local\Programs\Python\Python312\Lib\site-packages\django\core\management\base.py", line 486, in check
    all_issues = checks.run_checks(
                 ^^^^^^^^^^^^^^^^^^
  File "C:\Users\Administrator\AppData\Local\Programs\Python\Python312\Lib\site-packages\django\core\checks\registry.py", line 88, in run_checks
    new_errors = check(app_configs=app_configs, databases=databases)
                 ^^^^^^^^^^^^^^^^^^^^^^^^^^^^^^^^^^^^^^^^^^^^^^^^^^^
  File "C:\Users\Administrator\AppData\Local\Programs\Python\Python312\Lib\site-packages\django\core\checks\urls.py", line 136, in check_custom_error_handlers
    handler = resolver.resolve_error_handler(status_code)
              ^^^^^^^^^^^^^^^^^^^^^^^^^^^^^^^^^^^^^^^^^^^
  File "C:\Users\Administrator\AppData\Local\Programs\Python\Python312\Lib\site-packages\django\urls\resolvers.py", line 732, in resolve_error_handler
    callback = getattr(self.urlconf_module, "handler%s" % view_type, None)
                       ^^^^^^^^^^^^^^^^^^^
  File "C:\Users\Administrator\AppData\Local\Programs\Python\Python312\Lib\site-packages\django\utils\functional.py", line 47, in __get__
    res = instance.__dict__[self.name] = self.func(instance)
                                         ^^^^^^^^^^^^^^^^^^^
  File "C:\Users\Administrator\AppData\Local\Programs\Python\Python312\Lib\site-packages\django\urls\resolvers.py", line 711, in urlconf_module
    return import_module(self.urlconf_name)
           ^^^^^^^^^^^^^^^^^^^^^^^^^^^^^^^^
  File "C:\Users\Administrator\AppData\Local\Programs\Python\Python312\Lib\importlib\__init__.py", line 90, in import_module
    return _bootstrap._gcd_import(name[level:], package, level)
           ^^^^^^^^^^^^^^^^^^^^^^^^^^^^^^^^^^^^^^^^^^^^^^^^^^^^
  File "<frozen importlib._bootstrap>", line 1387, in _gcd_import
  File "<frozen importlib._bootstrap>", line 1360, in _find_and_load
  File "<frozen importlib._bootstrap>", line 1331, in _find_and_load_unlocked
  File "<frozen importlib._bootstrap>", line 935, in _load_unlocked
  File "<frozen importlib._bootstrap_external>", line 995, in exec_module
  File "<frozen importlib._bootstrap>", line 488, in _call_with_frames_removed
  File "C:\Users\Administrator\Desktop\Ticket\MUSEUM_BOT\MUSEUM_BOT\urls.py", line 22, in <module>
    path('ticket/', include("ticket.urls"))
                    ^^^^^^^^^^^^^^^^^^^^^^
  File "C:\Users\Administrator\AppData\Local\Programs\Python\Python312\Lib\site-packages\django\urls\conf.py", line 39, in include
    urlconf_module = import_module(urlconf_module)
                     ^^^^^^^^^^^^^^^^^^^^^^^^^^^^^
  File "C:\Users\Administrator\AppData\Local\Programs\Python\Python312\Lib\importlib\__init__.py", line 90, in import_module
    return _bootstrap._gcd_import(name[level:], package, level)
           ^^^^^^^^^^^^^^^^^^^^^^^^^^^^^^^^^^^^^^^^^^^^^^^^^^^^
  File "<frozen importlib._bootstrap>", line 1387, in _gcd_import
  File "<frozen importlib._bootstrap>", line 1360, in _find_and_load
  File "<frozen importlib._bootstrap>", line 1331, in _find_and_load_unlocked
  File "<frozen importlib._bootstrap>", line 935, in _load_unlocked
  File "<frozen importlib._bootstrap_external>", line 995, in exec_module
  File "<frozen importlib._bootstrap>", line 488, in _call_with_frames_removed
  File "C:\Users\Administrator\Desktop\Ticket\MUSEUM_BOT\ticket\urls.py", line 3, in <module>
    from . import views
  File "C:\Users\Administrator\Desktop\Ticket\MUSEUM_BOT\ticket\views.py", line 151
    response_json =
                    ^
SyntaxError: invalid syntax
C:\Users\Administrator\Desktop\Ticket\MUSEUM_BOT\ticket\views.py changed, reloading.
Watching for file changes with StatReloader
Performing system checks...

System check identified no issues (0 silenced).
August 23, 2024 - 13:15:18
Django version 5.1, using settings 'MUSEUM_BOT.settings'
Starting development server at http://127.0.0.1:6969/
Quit the server with CTRL-BREAK.

C:\Users\Administrator\Desktop\Ticket\MUSEUM_BOT\ticket\views.py changed, reloading.
Watching for file changes with StatReloader
Performing system checks...

System check identified no issues (0 silenced).
August 23, 2024 - 13:15:21
Django version 5.1, using settings 'MUSEUM_BOT.settings'
Starting development server at http://127.0.0.1:6969/
Quit the server with CTRL-BREAK.

<class 'str'>
user : give me json in {} not in [{}]
ai json : {"users": [], "your_response_back_to_user": "Sure!  How many tickets would you like to book?", "confirm": false}

Dict Detected
Internal Server Error: /ticket/
Traceback (most recent call last):
  File "C:\Users\Administrator\AppData\Local\Programs\Python\Python312\Lib\site-packages\django\core\handlers\exception.py", line 55, in inner
    response = get_response(request)
               ^^^^^^^^^^^^^^^^^^^^^
  File "C:\Users\Administrator\AppData\Local\Programs\Python\Python312\Lib\site-packages\django\core\handlers\base.py", line 197, in _get_response
    response = wrapped_callback(request, *callback_args, **callback_kwargs)
               ^^^^^^^^^^^^^^^^^^^^^^^^^^^^^^^^^^^^^^^^^^^^^^^^^^^^^^^^^^^^
  File "C:\Users\Administrator\AppData\Local\Programs\Python\Python312\Lib\site-packages\django\contrib\auth\decorators.py", line 60, in _view_wrapper
    return view_func(request, *args, **kwargs)
           ^^^^^^^^^^^^^^^^^^^^^^^^^^^^^^^^^^^
  File "C:\Users\Administrator\Desktop\Ticket\MUSEUM_BOT\ticket\views.py", line 151, in index
    response_json = json.loads(response_json)
                    ^^^^^^^^^^^^^^^^^^^^^^^^^
  File "C:\Users\Administrator\AppData\Local\Programs\Python\Python312\Lib\json\__init__.py", line 339, in loads
    raise TypeError(f'the JSON object must be str, bytes or bytearray, '
TypeError: the JSON object must be str, bytes or bytearray, not GenerateContentResponse
[23/Aug/2024 13:15:42] "POST /ticket/ HTTP/1.1" 500 81516
C:\Users\Administrator\Desktop\Ticket\MUSEUM_BOT\ticket\views.py changed, reloading.
Watching for file changes with StatReloader
Performing system checks...

System check identified no issues (0 silenced).
August 23, 2024 - 13:16:15
Django version 5.1, using settings 'MUSEUM_BOT.settings'
Starting development server at http://127.0.0.1:6969/
Quit the server with CTRL-BREAK.

C:\Users\Administrator\Desktop\Ticket\MUSEUM_BOT\ticket\views.py changed, reloading.
Watching for file changes with StatReloader
Performing system checks...

System check identified no issues (0 silenced).
August 23, 2024 - 13:16:20
Django version 5.1, using settings 'MUSEUM_BOT.settings'
Starting development server at http://127.0.0.1:6969/
Quit the server with CTRL-BREAK.

C:\Users\Administrator\Desktop\Ticket\MUSEUM_BOT\ticket\views.py changed, reloading.
Watching for file changes with StatReloader
Performing system checks...

System check identified no issues (0 silenced).
August 23, 2024 - 13:16:31
Django version 5.1, using settings 'MUSEUM_BOT.settings'
Starting development server at http://127.0.0.1:6969/
Quit the server with CTRL-BREAK.

<class 'str'>
user : give me json in {} not in [{}]
ai json : {"users": [{"user_info": {"name": "null", "age": null, "indian": null, "student": null, "ticket_type": null, "day": null, "month": null, "year": null}}], "your_response_back_to_user": "Hello! Welcome to Albert Hall Museum Jaipur. So,  you want to book tickets?  How many people are coming along? ", "confirm": false}


Dict Detected
[
  {
    "users": [
      {
        "user_info": {
          "name": "null",
          "age": null,
          "indian": null,
          "student": null,
          "ticket_type": null,
          "day": null,
          "month": null,
          "year": null
        }
      }
    ],
    "your_response_back_to_user": "Hello! Welcome to Albert Hall Museum Jaipur. So,  you want to book tickets?  How many people are coming along? ",
    "confirm": false
  }
]

[23/Aug/2024 13:16:42] "POST /ticket/ HTTP/1.1" 200 427
C:\Users\Administrator\Desktop\Ticket\MUSEUM_BOT\ticket\views.py changed, reloading.
Watching for file changes with StatReloader
Performing system checks...

System check identified no issues (0 silenced).
August 23, 2024 - 13:17:33
Django version 5.1, using settings 'MUSEUM_BOT.settings'
Starting development server at http://127.0.0.1:6969/
Quit the server with CTRL-BREAK.

C:\Users\Administrator\Desktop\Ticket\MUSEUM_BOT\ticket\views.py changed, reloading.
Watching for file changes with StatReloader
Performing system checks...

System check identified no issues (0 silenced).
August 23, 2024 - 13:17:57
Django version 5.1, using settings 'MUSEUM_BOT.settings'
Starting development server at http://127.0.0.1:6969/
Quit the server with CTRL-BREAK.

C:\Users\Administrator\Desktop\Ticket\MUSEUM_BOT\ticket\views.py changed, reloading.
Watching for file changes with StatReloader
Performing system checks...

System check identified no issues (0 silenced).
August 23, 2024 - 13:18:00
Django version 5.1, using settings 'MUSEUM_BOT.settings'
Starting development server at http://127.0.0.1:6969/
Quit the server with CTRL-BREAK.

<class 'str'>
user : give me json in {} not in [{}]
ai json : {"users": [{"user_info": {"name": null, "age": null, "indian": null, "student": null, "ticket_type": null, "day": null, "month": null, "year": null}}], "your_response_back_to_user": "Hello, Welcome to Albert Hall Museum ticket booking!  Let's get you set up. How many tickets would you like?", "confirm": false}

Dict Detected
[
  {
    "users": [
      {
        "user_info": {
          "name": null,
          "age": null,
          "indian": null,
          "student": null,
          "ticket_type": null,
          "day": null,
          "month": null,
          "year": null
        }
      }
    ],
    "your_response_back_to_user": "Hello, Welcome to Albert Hall Museum ticket booking!  Let's get you set up. How many tickets would you like?",
    "confirm": false
  }
]

Internal Server Error: /ticket/
Traceback (most recent call last):
  File "C:\Users\Administrator\AppData\Local\Programs\Python\Python312\Lib\site-packages\django\core\handlers\exception.py", line 55, in inner
    response = get_response(request)
               ^^^^^^^^^^^^^^^^^^^^^
  File "C:\Users\Administrator\AppData\Local\Programs\Python\Python312\Lib\site-packages\django\core\handlers\base.py", line 197, in _get_response
    response = wrapped_callback(request, *callback_args, **callback_kwargs)
               ^^^^^^^^^^^^^^^^^^^^^^^^^^^^^^^^^^^^^^^^^^^^^^^^^^^^^^^^^^^^
  File "C:\Users\Administrator\AppData\Local\Programs\Python\Python312\Lib\site-packages\django\contrib\auth\decorators.py", line 60, in _view_wrapper
    return view_func(request, *args, **kwargs)
           ^^^^^^^^^^^^^^^^^^^^^^^^^^^^^^^^^^^
  File "C:\Users\Administrator\Desktop\Ticket\MUSEUM_BOT\ticket\views.py", line 220, in index
    "response": response_json.text,
                ^^^^^^^^^^^^^^^^^^
AttributeError: 'list' object has no attribute 'text'
[23/Aug/2024 13:18:15] "POST /ticket/ HTTP/1.1" 500 74073
C:\Users\Administrator\Desktop\Ticket\MUSEUM_BOT\ticket\views.py changed, reloading.
Watching for file changes with StatReloader
Performing system checks...

System check identified no issues (0 silenced).
August 23, 2024 - 13:19:07
Django version 5.1, using settings 'MUSEUM_BOT.settings'
Starting development server at http://127.0.0.1:6969/
Quit the server with CTRL-BREAK.

<class 'str'>
user : give me json in {} not in [{}]
ai json : {"users": [], "your_response_back_to_user": "Hello! Welcome to the Albert Hall Museum ticket booking system! Let's get you those tickets. First, tell me how many people are coming?  ", "confirm": false}

Dict Detected
[
  {
    "users": [],
    "your_response_back_to_user": "Hello! Welcome to the Albert Hall Museum ticket booking system! Let's get you those tickets. First, tell me how many people are coming?  ",
    "confirm": false
  }
]

Internal Server Error: /ticket/
Traceback (most recent call last):
  File "C:\Users\Administrator\AppData\Local\Programs\Python\Python312\Lib\site-packages\django\core\handlers\exception.py", line 55, in inner
    response = get_response(request)
               ^^^^^^^^^^^^^^^^^^^^^
  File "C:\Users\Administrator\AppData\Local\Programs\Python\Python312\Lib\site-packages\django\core\handlers\base.py", line 197, in _get_response
    response = wrapped_callback(request, *callback_args, **callback_kwargs)
               ^^^^^^^^^^^^^^^^^^^^^^^^^^^^^^^^^^^^^^^^^^^^^^^^^^^^^^^^^^^^
  File "C:\Users\Administrator\AppData\Local\Programs\Python\Python312\Lib\site-packages\django\contrib\auth\decorators.py", line 60, in _view_wrapper
    return view_func(request, *args, **kwargs)
           ^^^^^^^^^^^^^^^^^^^^^^^^^^^^^^^^^^^
  File "C:\Users\Administrator\Desktop\Ticket\MUSEUM_BOT\ticket\views.py", line 220, in index
    "response": response.text,
                ^^^^^^^^^
NameError: name 'responsen' is not defined. Did you mean: 'response'?
[23/Aug/2024 13:19:19] "POST /ticket/ HTTP/1.1" 500 73391
C:\Users\Administrator\Desktop\Ticket\MUSEUM_BOT\ticket\views.py changed, reloading.
Watching for file changes with StatReloader
Performing system checks...

System check identified no issues (0 silenced).
August 23, 2024 - 13:20:24
Django version 5.1, using settings 'MUSEUM_BOT.settings'
Starting development server at http://127.0.0.1:6969/
Quit the server with CTRL-BREAK.