
[17/Aug/2024 19:44:42] "GET /ticket/ HTTP/1.1" 200 13
[17/Aug/2024 19:44:44] "GET /ticket/ HTTP/1.1" 200 13
[17/Aug/2024 19:44:53] "GET /ticket/ HTTP/1.1" 200 13
C:\Users\Administrator\Desktop\Ticket\MUSEUM_BOT\ticket\views.py changed, reloading.
Watching for file changes with StatReloader
Performing system checks...

System check identified no issues (0 silenced).

You have 18 unapplied migration(s). Your project may not work properly until you apply the migrations for app(s): admin, auth, contenttypes, sessions.
Run 'python manage.py migrate' to apply them.
August 17, 2024 - 19:47:03
Django version 5.1, using settings 'MUSEUM_BOT.settings'
Starting development server at http://127.0.0.1:8000/
Quit the server with CTRL-BREAK.

C:\Users\Administrator\Desktop\Ticket\MUSEUM_BOT\ticket\views.py changed, reloading.
Watching for file changes with StatReloader
Performing system checks...

System check identified no issues (0 silenced).
s, sessions.
Run 'python manage.py migrate' to apply them.                        y until you apply the migrations for app(s): admin, auth, contenttype
August 17, 2024 - 19:47:10
Django version 5.1, using settings 'MUSEUM_BOT.settings'
Starting development server at http://127.0.0.1:8000/
Quit the server with CTRL-BREAK.

[17/Aug/2024 19:47:26] "GET /ticket/ HTTP/1.1" 200 1100
[17/Aug/2024 19:47:26] "GET /static/ticket/styles.css HTTP/1.1" 200 409
[17/Aug/2024 19:47:32] "GET /ticket/?q=hi+mf HTTP/1.1" 200 1100      09
[17/Aug/2024 19:48:54] "GET /ticket/?q=hi+mf HTTP/1.1" 200 1098      
[17/Aug/2024 19:49:19] "GET /ticket/?q=hey+bri HTTP/1.1" 200 1098    
[17/Aug/2024 19:49:29] "GET /ticket/?q=hIIIIIIIIIIIIIIII HTTP/1.1" 200 1098                                                               0 1098
C:\Users\Administrator\Desktop\Ticket\MUSEUM_BOT\ticket\urls.py changed, reloading.
Watching for file changes with StatReloader
Performing system checks...

Exception in thread django-main-thread:
Traceback (most recent call last):
  File "C:\Users\Administrator\AppData\Local\Programs\Python\Python312\Lib\threading.py", line 1073, in _bootstrap_inner
    self.run()
  File "C:\Users\Administrator\AppData\Local\Programs\Python\Python312\Lib\threading.py", line 1010, in run
    self._target(*self._args, **self._kwargs)
  File "C:\Users\Administrator\AppData\Local\Programs\Python\Python312\Lib\site-packages\django\utils\autoreload.py", line 64, in wrapper 
    fn(*args, **kwargs)
  File "C:\Users\Administrator\AppData\Local\Programs\Python\Python312\Lib\site-packages\django\core\management\commands\runserver.py", line 134, in inner_run
    self.check(display_num_errors=True)
  File "C:\Users\Administrator\AppData\Local\Programs\Python\Python312\Lib\site-packages\django\core\management\base.py", line 486, in check
    all_issues = checks.run_checks(
                 ^^^^^^^^^^^^^^^^^^
  File "C:\Users\Administrator\AppData\Local\Programs\Python\Python312\Lib\site-packages\django\core\checks\registry.py", line 88, in run_checks
    new_errors = check(app_configs=app_configs, databases=databases) 
                 ^^^^^^^^^^^^^^^^^^^^^^^^^^^^^^^^^^^^^^^^^^^^^^^^^^^ 
  File "C:\Users\Administrator\AppData\Local\Programs\Python\Python312\Lib\site-packages\django\core\checks\urls.py", line 136, in check_custom_error_handlers
    handler = resolver.resolve_error_handler(status_code)
              ^^^^^^^^^^^^^^^^^^^^^^^^^^^^^^^^^^^^^^^^^^^
  File "C:\Users\Administrator\AppData\Local\Programs\Python\Python312\Lib\site-packages\django\urls\resolvers.py", line 732, in resolve_error_handler
    callback = getattr(self.urlconf_module, "handler%s" % view_type, 
None)
                       ^^^^^^^^^^^^^^^^^^^
  File "C:\Users\Administrator\AppData\Local\Programs\Python\Python312\Lib\site-packages\django\utils\functional.py", line 47, in __get__ 
    res = instance.__dict__[self.name] = self.func(instance)
                                         ^^^^^^^^^^^^^^^^^^^
  File "C:\Users\Administrator\AppData\Local\Programs\Python\Python312\Lib\site-packages\django\urls\resolvers.py", line 711, in urlconf_module
    return import_module(self.urlconf_name)
           ^^^^^^^^^^^^^^^^^^^^^^^^^^^^^^^^
  File "C:\Users\Administrator\AppData\Local\Programs\Python\Python312\Lib\importlib\__init__.py", line 90, in import_module
    return _bootstrap._gcd_import(name[level:], package, level)      
           ^^^^^^^^^^^^^^^^^^^^^^^^^^^^^^^^^^^^^^^^^^^^^^^^^^^^      
  File "<frozen importlib._bootstrap>", line 1387, in _gcd_import    
  File "<frozen importlib._bootstrap>", line 1360, in _find_and_load 
  File "<frozen importlib._bootstrap>", line 1331, in _find_and_load_unlocked
  File "<frozen importlib._bootstrap>", line 935, in _load_unlocked  
  File "<frozen importlib._bootstrap_external>", line 995, in exec_module
  File "<frozen importlib._bootstrap>", line 488, in _call_with_frames_removed
  File "C:\Users\Administrator\Desktop\Ticket\MUSEUM_BOT\MUSEUM_BOT\urls.py", line 22, in <module>
    path('ticket/', include("ticket.urls"))
                    ^^^^^^^^^^^^^^^^^^^^^^
  File "C:\Users\Administrator\AppData\Local\Programs\Python\Python312\Lib\site-packages\django\urls\conf.py", line 39, in include        
    urlconf_module = import_module(urlconf_module)
                     ^^^^^^^^^^^^^^^^^^^^^^^^^^^^^
  File "C:\Users\Administrator\AppData\Local\Programs\Python\Python312\Lib\importlib\__init__.py", line 90, in import_module
    return _bootstrap._gcd_import(name[level:], package, level)      
           ^^^^^^^^^^^^^^^^^^^^^^^^^^^^^^^^^^^^^^^^^^^^^^^^^^^^      
  File "<frozen importlib._bootstrap>", line 1387, in _gcd_import    
  File "<frozen importlib._bootstrap>", line 1360, in _find_and_load 
  File "<frozen importlib._bootstrap>", line 1331, in _find_and_load_unlocked
  File "<frozen importlib._bootstrap>", line 935, in _load_unlocked  
  File "<frozen importlib._bootstrap_external>", line 995, in exec_module
  File "<frozen importlib._bootstrap>", line 488, in _call_with_frames_removed
  File "C:\Users\Administrator\Desktop\Ticket\MUSEUM_BOT\ticket\urls.py", line 7, in <module>
    path("login", views.login_view, name="login"),
                  ^^^^^^^^^^^^^^^^
AttributeError: module 'ticket.views' has no attribute 'login_view'  
C:\Users\Administrator\Desktop\Ticket\MUSEUM_BOT\ticket\models.py changed, reloading.
Watching for file changes with StatReloader
Exception in thread django-main-thread:
Traceback (most recent call last):
  File "C:\Users\Administrator\AppData\Local\Programs\Python\Python312\Lib\threading.py", line 1073, in _bootstrap_inner
    self.run()
  File "C:\Users\Administrator\AppData\Local\Programs\Python\Python312\Lib\threading.py", line 1010, in run
    self._target(*self._args, **self._kwargs)
  File "C:\Users\Administrator\AppData\Local\Programs\Python\Python312\Lib\site-packages\django\utils\autoreload.py", line 64, in wrapper 
    fn(*args, **kwargs)
  File "C:\Users\Administrator\AppData\Local\Programs\Python\Python312\Lib\site-packages\django\core\management\commands\runserver.py", line 126, in inner_run
    autoreload.raise_last_exception()
  File "C:\Users\Administrator\AppData\Local\Programs\Python\Python312\Lib\site-packages\django\utils\autoreload.py", line 87, in raise_last_exception
    raise _exception[1]
  File "C:\Users\Administrator\AppData\Local\Programs\Python\Python312\Lib\site-packages\django\core\management\__init__.py", line 394, in execute
    autoreload.check_errors(django.setup)()
  File "C:\Users\Administrator\AppData\Local\Programs\Python\Python312\Lib\site-packages\django\utils\autoreload.py", line 64, in wrapper 
    fn(*args, **kwargs)
  File "C:\Users\Administrator\AppData\Local\Programs\Python\Python312\Lib\site-packages\django\__init__.py", line 24, in setup
    apps.populate(settings.INSTALLED_APPS)
  File "C:\Users\Administrator\AppData\Local\Programs\Python\Python312\Lib\site-packages\django\apps\registry.py", line 116, in populate  
    app_config.import_models()
  File "C:\Users\Administrator\AppData\Local\Programs\Python\Python312\Lib\site-packages\django\apps\config.py", line 269, in import_models
    self.models_module = import_module(models_module_name)
                         ^^^^^^^^^^^^^^^^^^^^^^^^^^^^^^^^^
  File "C:\Users\Administrator\AppData\Local\Programs\Python\Python312\Lib\importlib\__init__.py", line 90, in import_module
    return _bootstrap._gcd_import(name[level:], package, level)      
           ^^^^^^^^^^^^^^^^^^^^^^^^^^^^^^^^^^^^^^^^^^^^^^^^^^^^      
  File "<frozen importlib._bootstrap>", line 1387, in _gcd_import    
  File "<frozen importlib._bootstrap>", line 1360, in _find_and_load 
  File "<frozen importlib._bootstrap>", line 1331, in _find_and_load_unlocked
  File "<frozen importlib._bootstrap>", line 935, in _load_unlocked  
  File "<frozen importlib._bootstrap_external>", line 995, in exec_module
  File "<frozen importlib._bootstrap>", line 488, in _call_with_frames_removed
  File "C:\Users\Administrator\Desktop\Ticket\MUSEUM_BOT\ticket\models.py", line 7, in <module>
    from .models import User
ImportError: cannot import name 'User' from partially initialized module 'ticket.models' (most likely due to a circular import) (C:\Users\Administrator\Desktop\Ticket\MUSEUM_BOT\ticket\models.py)
C:\Users\Administrator\Desktop\Ticket\MUSEUM_BOT\ticket\models.py changed, reloading.
Watching for file changes with StatReloader
Exception in thread django-main-thread:
Traceback (most recent call last):
  File "C:\Users\Administrator\AppData\Local\Programs\Python\Python312\Lib\threading.py", line 1073, in _bootstrap_inner
    self.run()
  File "C:\Users\Administrator\AppData\Local\Programs\Python\Python312\Lib\threading.py", line 1010, in run
    self._target(*self._args, **self._kwargs)
  File "C:\Users\Administrator\AppData\Local\Programs\Python\Python312\Lib\site-packages\django\utils\autoreload.py", line 64, in wrapper 
    fn(*args, **kwargs)
  File "C:\Users\Administrator\AppData\Local\Programs\Python\Python312\Lib\site-packages\django\core\management\commands\runserver.py", line 126, in inner_run
    autoreload.raise_last_exception()
  File "C:\Users\Administrator\AppData\Local\Programs\Python\Python312\Lib\site-packages\django\utils\autoreload.py", line 87, in raise_last_exception
    raise _exception[1]
  File "C:\Users\Administrator\AppData\Local\Programs\Python\Python312\Lib\site-packages\django\core\management\__init__.py", line 394, in execute
    autoreload.check_errors(django.setup)()
  File "C:\Users\Administrator\AppData\Local\Programs\Python\Python312\Lib\site-packages\django\utils\autoreload.py", line 64, in wrapper 
    fn(*args, **kwargs)
  File "C:\Users\Administrator\AppData\Local\Programs\Python\Python312\Lib\site-packages\django\__init__.py", line 24, in setup
    apps.populate(settings.INSTALLED_APPS)
  File "C:\Users\Administrator\AppData\Local\Programs\Python\Python312\Lib\site-packages\django\apps\registry.py", line 116, in populate  
    app_config.import_models()
  File "C:\Users\Administrator\AppData\Local\Programs\Python\Python312\Lib\site-packages\django\apps\config.py", line 269, in import_models
    self.models_module = import_module(models_module_name)
                         ^^^^^^^^^^^^^^^^^^^^^^^^^^^^^^^^^
  File "C:\Users\Administrator\AppData\Local\Programs\Python\Python312\Lib\importlib\__init__.py", line 90, in import_module
    return _bootstrap._gcd_import(name[level:], package, level)      
           ^^^^^^^^^^^^^^^^^^^^^^^^^^^^^^^^^^^^^^^^^^^^^^^^^^^^      
  File "<frozen importlib._bootstrap>", line 1387, in _gcd_import    
  File "<frozen importlib._bootstrap>", line 1360, in _find_and_load 
  File "<frozen importlib._bootstrap>", line 1331, in _find_and_load_unlocked
  File "<frozen importlib._bootstrap>", line 935, in _load_unlocked  
  File "<frozen importlib._bootstrap_external>", line 995, in exec_module
  File "<frozen importlib._bootstrap>", line 488, in _call_with_frames_removed
  File "C:\Users\Administrator\Desktop\Ticket\MUSEUM_BOT\ticket\models.py", line 7, in <module>
    from .models import User
ImportError: cannot import name 'User' from partially initialized module 'ticket.models' (most likely due to a circular import) (C:\Users\Administrator\Desktop\Ticket\MUSEUM_BOT\ticket\models.py)
C:\Users\Administrator\Desktop\Ticket\MUSEUM_BOT\ticket\models.py changed, reloading.
Watching for file changes with StatReloader
Exception in thread django-main-thread:
Traceback (most recent call last):
  File "C:\Users\Administrator\AppData\Local\Programs\Python\Python312\Lib\threading.py", line 1073, in _bootstrap_inner
    self.run()
  File "C:\Users\Administrator\AppData\Local\Programs\Python\Python312\Lib\threading.py", line 1010, in run
    self._target(*self._args, **self._kwargs)
  File "C:\Users\Administrator\AppData\Local\Programs\Python\Python312\Lib\site-packages\django\utils\autoreload.py", line 64, in wrapper 
    fn(*args, **kwargs)
  File "C:\Users\Administrator\AppData\Local\Programs\Python\Python312\Lib\site-packages\django\core\management\commands\runserver.py", line 126, in inner_run
    autoreload.raise_last_exception()
  File "C:\Users\Administrator\AppData\Local\Programs\Python\Python312\Lib\site-packages\django\utils\autoreload.py", line 87, in raise_last_exception
    raise _exception[1]
  File "C:\Users\Administrator\AppData\Local\Programs\Python\Python312\Lib\site-packages\django\core\management\__init__.py", line 394, in execute
    autoreload.check_errors(django.setup)()
  File "C:\Users\Administrator\AppData\Local\Programs\Python\Python312\Lib\site-packages\django\utils\autoreload.py", line 64, in wrapper 
    fn(*args, **kwargs)
  File "C:\Users\Administrator\AppData\Local\Programs\Python\Python312\Lib\site-packages\django\__init__.py", line 24, in setup
    apps.populate(settings.INSTALLED_APPS)
  File "C:\Users\Administrator\AppData\Local\Programs\Python\Python312\Lib\site-packages\django\apps\registry.py", line 116, in populate  
    app_config.import_models()
  File "C:\Users\Administrator\AppData\Local\Programs\Python\Python312\Lib\site-packages\django\apps\config.py", line 269, in import_models
    self.models_module = import_module(models_module_name)
                         ^^^^^^^^^^^^^^^^^^^^^^^^^^^^^^^^^
  File "C:\Users\Administrator\AppData\Local\Programs\Python\Python312\Lib\importlib\__init__.py", line 90, in import_module
    return _bootstrap._gcd_import(name[level:], package, level)      
           ^^^^^^^^^^^^^^^^^^^^^^^^^^^^^^^^^^^^^^^^^^^^^^^^^^^^      
  File "<frozen importlib._bootstrap>", line 1387, in _gcd_import    
  File "<frozen importlib._bootstrap>", line 1360, in _find_and_load 
  File "<frozen importlib._bootstrap>", line 1331, in _find_and_load_unlocked
  File "<frozen importlib._bootstrap>", line 935, in _load_unlocked  
  File "<frozen importlib._bootstrap_external>", line 995, in exec_module
  File "<frozen importlib._bootstrap>", line 488, in _call_with_frames_removed
  File "C:\Users\Administrator\Desktop\Ticket\MUSEUM_BOT\ticket\models.py", line 7, in <module>
    from .models import User
ImportError: cannot import name 'User' from partially initialized module 'ticket.models' (most likely due to a circular import) (C:\Users\Administrator\Desktop\Ticket\MUSEUM_BOT\ticket\models.py)
C:\Users\Administrator\Desktop\Ticket\MUSEUM_BOT\ticket\models.py changed, reloading.
Watching for file changes with StatReloader
Exception in thread django-main-thread:
Traceback (most recent call last):
  File "C:\Users\Administrator\AppData\Local\Programs\Python\Python312\Lib\threading.py", line 1073, in _bootstrap_inner
    self.run()
  File "C:\Users\Administrator\AppData\Local\Programs\Python\Python312\Lib\threading.py", line 1010, in run
    self._target(*self._args, **self._kwargs)
  File "C:\Users\Administrator\AppData\Local\Programs\Python\Python312\Lib\site-packages\django\utils\autoreload.py", line 64, in wrapper 
    fn(*args, **kwargs)
  File "C:\Users\Administrator\AppData\Local\Programs\Python\Python312\Lib\site-packages\django\core\management\commands\runserver.py", line 126, in inner_run
    autoreload.raise_last_exception()
  File "C:\Users\Administrator\AppData\Local\Programs\Python\Python312\Lib\site-packages\django\utils\autoreload.py", line 87, in raise_last_exception
    raise _exception[1]
  File "C:\Users\Administrator\AppData\Local\Programs\Python\Python312\Lib\site-packages\django\core\management\__init__.py", line 394, in execute
    autoreload.check_errors(django.setup)()
  File "C:\Users\Administrator\AppData\Local\Programs\Python\Python312\Lib\site-packages\django\utils\autoreload.py", line 64, in wrapper 
    fn(*args, **kwargs)
  File "C:\Users\Administrator\AppData\Local\Programs\Python\Python312\Lib\site-packages\django\__init__.py", line 24, in setup
    apps.populate(settings.INSTALLED_APPS)
  File "C:\Users\Administrator\AppData\Local\Programs\Python\Python312\Lib\site-packages\django\apps\registry.py", line 116, in populate  
    app_config.import_models()
  File "C:\Users\Administrator\AppData\Local\Programs\Python\Python312\Lib\site-packages\django\apps\config.py", line 269, in import_models
    self.models_module = import_module(models_module_name)
                         ^^^^^^^^^^^^^^^^^^^^^^^^^^^^^^^^^
  File "C:\Users\Administrator\AppData\Local\Programs\Python\Python312\Lib\importlib\__init__.py", line 90, in import_module
    return _bootstrap._gcd_import(name[level:], package, level)      
           ^^^^^^^^^^^^^^^^^^^^^^^^^^^^^^^^^^^^^^^^^^^^^^^^^^^^      
  File "<frozen importlib._bootstrap>", line 1387, in _gcd_import    
  File "<frozen importlib._bootstrap>", line 1360, in _find_and_load 
  File "<frozen importlib._bootstrap>", line 1331, in _find_and_load_unlocked
  File "<frozen importlib._bootstrap>", line 935, in _load_unlocked  
  File "<frozen importlib._bootstrap_external>", line 995, in exec_module
  File "<frozen importlib._bootstrap>", line 488, in _call_with_frames_removed
  File "C:\Users\Administrator\Desktop\Ticket\MUSEUM_BOT\ticket\models.py", line 7, in <module>
    from .models import User
ImportError: cannot import name 'User' from partially initialized module 'ticket.models' (most likely due to a circular import) (C:\Users\Administrator\Desktop\Ticket\MUSEUM_BOT\ticket\models.py)
C:\Users\Administrator\Desktop\Ticket\MUSEUM_BOT\ticket\models.py changed, reloading.
Watching for file changes with StatReloader
Exception in thread django-main-thread:
Traceback (most recent call last):
  File "C:\Users\Administrator\AppData\Local\Programs\Python\Python312\Lib\threading.py", line 1073, in _bootstrap_inner
    self.run()
  File "C:\Users\Administrator\AppData\Local\Programs\Python\Python312\Lib\threading.py", line 1010, in run
    self._target(*self._args, **self._kwargs)
  File "C:\Users\Administrator\AppData\Local\Programs\Python\Python312\Lib\site-packages\django\utils\autoreload.py", line 64, in wrapper 
    fn(*args, **kwargs)
  File "C:\Users\Administrator\AppData\Local\Programs\Python\Python312\Lib\site-packages\django\core\management\commands\runserver.py", line 126, in inner_run
    autoreload.raise_last_exception()
  File "C:\Users\Administrator\AppData\Local\Programs\Python\Python312\Lib\site-packages\django\utils\autoreload.py", line 87, in raise_last_exception
    raise _exception[1]
  File "C:\Users\Administrator\AppData\Local\Programs\Python\Python312\Lib\site-packages\django\core\management\__init__.py", line 394, in execute
    autoreload.check_errors(django.setup)()
  File "C:\Users\Administrator\AppData\Local\Programs\Python\Python312\Lib\site-packages\django\utils\autoreload.py", line 64, in wrapper 
    fn(*args, **kwargs)
  File "C:\Users\Administrator\AppData\Local\Programs\Python\Python312\Lib\site-packages\django\__init__.py", line 24, in setup
    apps.populate(settings.INSTALLED_APPS)
  File "C:\Users\Administrator\AppData\Local\Programs\Python\Python312\Lib\site-packages\django\apps\registry.py", line 116, in populate  
    app_config.import_models()
  File "C:\Users\Administrator\AppData\Local\Programs\Python\Python312\Lib\site-packages\django\apps\config.py", line 269, in import_models
    self.models_module = import_module(models_module_name)
                         ^^^^^^^^^^^^^^^^^^^^^^^^^^^^^^^^^
  File "C:\Users\Administrator\AppData\Local\Programs\Python\Python312\Lib\importlib\__init__.py", line 90, in import_module
    return _bootstrap._gcd_import(name[level:], package, level)
           ^^^^^^^^^^^^^^^^^^^^^^^^^^^^^^^^^^^^^^^^^^^^^^^^^^^^      
  File "<frozen importlib._bootstrap>", line 1387, in _gcd_import    
  File "<frozen importlib._bootstrap>", line 1360, in _find_and_load 
  File "<frozen importlib._bootstrap>", line 1331, in _find_and_load_unlocked
  File "<frozen importlib._bootstrap>", line 935, in _load_unlocked  
  File "<frozen importlib._bootstrap_external>", line 995, in exec_module
  File "<frozen importlib._bootstrap>", line 488, in _call_with_frames_removed
  File "C:\Users\Administrator\Desktop\Ticket\MUSEUM_BOT\ticket\models.py", line 7, in <module>
    from .models import User
ImportError: cannot import name 'User' from partially initialized module 'ticket.models' (most likely due to a circular import) (C:\Users\Administrator\Desktop\Ticket\MUSEUM_BOT\ticket\models.py)
C:\Users\Administrator\Desktop\Ticket\MUSEUM_BOT\ticket\models.py changed, reloading.
Watching for file changes with StatReloader
Performing system checks...

Exception in thread django-main-thread:
Traceback (most recent call last):
  File "C:\Users\Administrator\AppData\Local\Programs\Python\Python312\Lib\threading.py", line 1073, in _bootstrap_inner
    self.run()
  File "C:\Users\Administrator\AppData\Local\Programs\Python\Python312\Lib\threading.py", line 1010, in run
    self._target(*self._args, **self._kwargs)
  File "C:\Users\Administrator\AppData\Local\Programs\Python\Python312\Lib\site-packages\django\utils\autoreload.py", line 64, in wrapper 
    fn(*args, **kwargs)
  File "C:\Users\Administrator\AppData\Local\Programs\Python\Python312\Lib\site-packages\django\core\management\commands\runserver.py", line 134, in inner_run
    self.check(display_num_errors=True)
  File "C:\Users\Administrator\AppData\Local\Programs\Python\Python312\Lib\site-packages\django\core\management\base.py", line 486, in check
    all_issues = checks.run_checks(
                 ^^^^^^^^^^^^^^^^^^
  File "C:\Users\Administrator\AppData\Local\Programs\Python\Python312\Lib\site-packages\django\core\checks\registry.py", line 88, in run_checks
    new_errors = check(app_configs=app_configs, databases=databases) 
                 ^^^^^^^^^^^^^^^^^^^^^^^^^^^^^^^^^^^^^^^^^^^^^^^^^^^ 
  File "C:\Users\Administrator\AppData\Local\Programs\Python\Python312\Lib\site-packages\django\core\checks\urls.py", line 136, in check_custom_error_handlers
    handler = resolver.resolve_error_handler(status_code)
              ^^^^^^^^^^^^^^^^^^^^^^^^^^^^^^^^^^^^^^^^^^^
  File "C:\Users\Administrator\AppData\Local\Programs\Python\Python312\Lib\site-packages\django\urls\resolvers.py", line 732, in resolve_error_handler
    callback = getattr(self.urlconf_module, "handler%s" % view_type, 
None)
                       ^^^^^^^^^^^^^^^^^^^
  File "C:\Users\Administrator\AppData\Local\Programs\Python\Python312\Lib\site-packages\django\utils\functional.py", line 47, in __get__ 
    res = instance.__dict__[self.name] = self.func(instance)
                                         ^^^^^^^^^^^^^^^^^^^
  File "C:\Users\Administrator\AppData\Local\Programs\Python\Python312\Lib\site-packages\django\urls\resolvers.py", line 711, in urlconf_module
    return import_module(self.urlconf_name)
           ^^^^^^^^^^^^^^^^^^^^^^^^^^^^^^^^
  File "C:\Users\Administrator\AppData\Local\Programs\Python\Python312\Lib\importlib\__init__.py", line 90, in import_module
    return _bootstrap._gcd_import(name[level:], package, level)      
           ^^^^^^^^^^^^^^^^^^^^^^^^^^^^^^^^^^^^^^^^^^^^^^^^^^^^      
  File "<frozen importlib._bootstrap>", line 1387, in _gcd_import    
  File "<frozen importlib._bootstrap>", line 1360, in _find_and_load 
  File "<frozen importlib._bootstrap>", line 1331, in _find_and_load_unlocked
  File "<frozen importlib._bootstrap>", line 935, in _load_unlocked  
  File "<frozen importlib._bootstrap_external>", line 995, in exec_module
  File "<frozen importlib._bootstrap>", line 488, in _call_with_frames_removed
  File "C:\Users\Administrator\Desktop\Ticket\MUSEUM_BOT\MUSEUM_BOT\urls.py", line 22, in <module>
    path('ticket/', include("ticket.urls"))
                    ^^^^^^^^^^^^^^^^^^^^^^
  File "C:\Users\Administrator\AppData\Local\Programs\Python\Python312\Lib\site-packages\django\urls\conf.py", line 39, in include        
    urlconf_module = import_module(urlconf_module)
                     ^^^^^^^^^^^^^^^^^^^^^^^^^^^^^
  File "C:\Users\Administrator\AppData\Local\Programs\Python\Python312\Lib\importlib\__init__.py", line 90, in import_module
    return _bootstrap._gcd_import(name[level:], package, level)      
           ^^^^^^^^^^^^^^^^^^^^^^^^^^^^^^^^^^^^^^^^^^^^^^^^^^^^      
  File "<frozen importlib._bootstrap>", line 1387, in _gcd_import    
  File "<frozen importlib._bootstrap>", line 1360, in _find_and_load 
  File "<frozen importlib._bootstrap>", line 1331, in _find_and_load_unlocked
  File "<frozen importlib._bootstrap>", line 935, in _load_unlocked  
  File "<frozen importlib._bootstrap_external>", line 995, in exec_module
  File "<frozen importlib._bootstrap>", line 488, in _call_with_frames_removed
  File "C:\Users\Administrator\Desktop\Ticket\MUSEUM_BOT\ticket\urls.py", line 7, in <module>
    path("login", views.login_view, name="login"),
                  ^^^^^^^^^^^^^^^^
AttributeError: module 'ticket.views' has no attribute 'login_view'  
C:\Users\Administrator\Desktop\Ticket\MUSEUM_BOT\ticket\models.py changed, reloading.
Watching for file changes with StatReloader
Exception in thread django-main-thread:
Traceback (most recent call last):
  File "C:\Users\Administrator\AppData\Local\Programs\Python\Python312\Lib\threading.py", line 1073, in _bootstrap_inner
    self.run()
  File "C:\Users\Administrator\AppData\Local\Programs\Python\Python312\Lib\threading.py", line 1010, in run
    self._target(*self._args, **self._kwargs)
  File "C:\Users\Administrator\AppData\Local\Programs\Python\Python312\Lib\site-packages\django\utils\autoreload.py", line 64, in wrapper 
    fn(*args, **kwargs)
  File "C:\Users\Administrator\AppData\Local\Programs\Python\Python312\Lib\site-packages\django\core\management\commands\runserver.py", line 126, in inner_run
    autoreload.raise_last_exception()
  File "C:\Users\Administrator\AppData\Local\Programs\Python\Python312\Lib\site-packages\django\utils\autoreload.py", line 87, in raise_last_exception
    raise _exception[1]
  File "C:\Users\Administrator\AppData\Local\Programs\Python\Python312\Lib\site-packages\django\core\management\__init__.py", line 394, in execute
    autoreload.check_errors(django.setup)()
  File "C:\Users\Administrator\AppData\Local\Programs\Python\Python312\Lib\site-packages\django\utils\autoreload.py", line 64, in wrapper 
    fn(*args, **kwargs)
  File "C:\Users\Administrator\AppData\Local\Programs\Python\Python312\Lib\site-packages\django\__init__.py", line 24, in setup
    apps.populate(settings.INSTALLED_APPS)
  File "C:\Users\Administrator\AppData\Local\Programs\Python\Python312\Lib\site-packages\django\apps\registry.py", line 116, in populate  
    app_config.import_models()
  File "C:\Users\Administrator\AppData\Local\Programs\Python\Python312\Lib\site-packages\django\apps\config.py", line 269, in import_models
    self.models_module = import_module(models_module_name)
                         ^^^^^^^^^^^^^^^^^^^^^^^^^^^^^^^^^
  File "C:\Users\Administrator\AppData\Local\Programs\Python\Python312\Lib\importlib\__init__.py", line 90, in import_module
    return _bootstrap._gcd_import(name[level:], package, level)      
           ^^^^^^^^^^^^^^^^^^^^^^^^^^^^^^^^^^^^^^^^^^^^^^^^^^^^      
  File "<frozen importlib._bootstrap>", line 1387, in _gcd_import    
  File "<frozen importlib._bootstrap>", line 1360, in _find_and_load 
  File "<frozen importlib._bootstrap>", line 1331, in _find_and_load_unlocked
  File "<frozen importlib._bootstrap>", line 935, in _load_unlocked  
  File "<frozen importlib._bootstrap_external>", line 995, in exec_module
  File "<frozen importlib._bootstrap>", line 488, in _call_with_frames_removed
  File "C:\Users\Administrator\Desktop\Ticket\MUSEUM_BOT\ticket\models.py", line 7, in <module>
    from .models import User
ImportError: cannot import name 'User' from partially initialized module 'ticket.models' (most likely due to a circular import) (C:\Users\Administrator\Desktop\Ticket\MUSEUM_BOT\ticket\models.py)
C:\Users\Administrator\Desktop\Ticket\MUSEUM_BOT\ticket\models.py changed, reloading.
Watching for file changes with StatReloader
Performing system checks...

Exception in thread django-main-thread:
Traceback (most recent call last):
  File "C:\Users\Administrator\AppData\Local\Programs\Python\Python312\Lib\threading.py", line 1073, in _bootstrap_inner
    self.run()
  File "C:\Users\Administrator\AppData\Local\Programs\Python\Python312\Lib\threading.py", line 1010, in run
    self._target(*self._args, **self._kwargs)
  File "C:\Users\Administrator\AppData\Local\Programs\Python\Python312\Lib\site-packages\django\utils\autoreload.py", line 64, in wrapper 
    fn(*args, **kwargs)
  File "C:\Users\Administrator\AppData\Local\Programs\Python\Python312\Lib\site-packages\django\core\management\commands\runserver.py", line 134, in inner_run
    self.check(display_num_errors=True)
  File "C:\Users\Administrator\AppData\Local\Programs\Python\Python312\Lib\site-packages\django\core\management\base.py", line 563, in check
    raise SystemCheckError(msg)
django.core.management.base.SystemCheckError: SystemCheckError: System check identified some issues:

ERRORS:
auth.User.groups: (fields.E304) Reverse accessor 'Group.user_set' for 'auth.User.groups' clashes with reverse accessor for 'ticket.User.groups'.
        HINT: Add or change a related_name argument to the definition for 'auth.User.groups' or 'ticket.User.groups'.
auth.User.user_permissions: (fields.E304) Reverse accessor 'Permission.user_set' for 'auth.User.user_permissions' clashes with reverse accPS C:\Users\Administrator\Desktop\Ticket\MUSEUM_BOT> python manage.py makemigrations ticket
SystemCheckError: System check identified some issues:

ERRORS:
auth.User.groups: (fields.E304) Reverse accessor 'Group.user_set' for 'auth.User.groups' clashes with reverse accessor for 'ticket.User.groups'.
        HINT: Add or change a related_name argument to the definition for 'auth.User.groups' or 'ticket.User.groups'.
auth.User.user_permissions: (fields.E304) Reverse accessor 'Permissioessor for 'ticket.User.user_permissions'.
        HINT: Add or change a related_name argument to the definition for 'auth.User.user_permissions' or 'ticket.User.user_permissions'. 
ticket.User.groups: (fields.E304) Reverse accessor 'Group.user_set' for 'ticket.User.groups' clashes with reverse accessor for 'auth.User.groups'.
        HINT: Add or change a related_name argument to the definition for 'ticket.User.groups' or 'auth.User.groups'.
ticket.User.user_permissions: (fields.E304) Reverse accessor 'Permission.user_set' for 'ticket.User.user_permissions' clashes with reverse accessor for 'auth.User.user_permissions'.
        HINT: Add or change a related_name argument to the definition for 'ticket.User.user_permissions' or 'auth.User.user_permissions'. 
PS C:\Users\Administrator\Desktop\Ticket\MUSEUM_BOT> python manage.py makemigrations user
SystemCheckError: System check identified some issues:

ERRORS:
auth.User.groups: (fields.E304) Reverse accessor 'Group.user_set' for 'auth.User.groups' clashes with reverse accessor for 'ticket.User.groups'.
        HINT: Add or change a related_name argument to the definition for 'auth.User.groups' or 'ticket.User.groups'.
PS C:\Users\Administrator\Desktop\Ticket\MUSEUM_BOT> python manage.py makemigrations user
Traceback (most recent call last):
  File "C:\Users\Administrator\AppData\Local\Programs\Python\Python312\Lib\site-packages\django\core\checks\urls.py", line 136, in check_custom_error_handlers
    handler = resolver.resolve_error_handler(status_code)
              ^^^^^^^^^^^^^^^^^^^^^^^^^^^^^^^^^^^^^^^^^^^
  File "C:\Users\Administrator\AppData\Local\Programs\Python\Python312\Lib\site-packages\django\urls\resolvers.py", line 732, in resolve_error_handler
    callback = getattr(self.urlconf_module, "handler%s" % view_type, 
None)
                       ^^^^^^^^^^^^^^^^^^^
  File "C:\Users\Administrator\AppData\Local\Programs\Python\Python312\Lib\site-packages\django\utils\functional.py", line 47, in __get__ 
    res = instance.__dict__[self.name] = self.func(instance)
                                         ^^^^^^^^^^^^^^^^^^^
  File "C:\Users\Administrator\AppData\Local\Programs\Python\Python312\Lib\site-packages\django\urls\resolvers.py", line 711, in urlconf_module
    return import_module(self.urlconf_name)
           ^^^^^^^^^^^^^^^^^^^^^^^^^^^^^^^^
  File "C:\Users\Administrator\AppData\Local\Programs\Python\Python312\Lib\importlib\__init__.py", line 90, in import_module
    return _bootstrap._gcd_import(name[level:], package, level)      
           ^^^^^^^^^^^^^^^^^^^^^^^^^^^^^^^^^^^^^^^^^^^^^^^^^^^^      
  File "<frozen importlib._bootstrap>", line 1387, in _gcd_import    
  File "<frozen importlib._bootstrap>", line 1360, in _find_and_load 
  File "<frozen importlib._bootstrap>", line 1331, in _find_and_load_unlocked
  File "<frozen importlib._bootstrap>", line 935, in _load_unlocked  
  File "<frozen importlib._bootstrap_external>", line 995, in exec_module
  File "<frozen importlib._bootstrap>", line 488, in _call_with_frames_removed
  File "C:\Users\Administrator\Desktop\Ticket\MUSEUM_BOT\MUSEUM_BOT\urls.py", line 22, in <module>
    path('ticket/', include("ticket.urls"))
                    ^^^^^^^^^^^^^^^^^^^^^^
  File "C:\Users\Administrator\AppData\Local\Programs\Python\Python312\Lib\site-packages\django\urls\conf.py", line 39, in include        
    urlconf_module = import_module(urlconf_module)
                     ^^^^^^^^^^^^^^^^^^^^^^^^^^^^^
  File "C:\Users\Administrator\AppData\Local\Programs\Python\Python312\Lib\importlib\__init__.py", line 90, in import_module
    return _bootstrap._gcd_import(name[level:], package, level)      
           ^^^^^^^^^^^^^^^^^^^^^^^^^^^^^^^^^^^^^^^^^^^^^^^^^^^^      
  File "<frozen importlib._bootstrap>", line 1387, in _gcd_import    
  File "<frozen importlib._bootstrap>", line 1360, in _find_and_load 
  File "<frozen importlib._bootstrap>", line 1331, in _find_and_load_unlocked
  File "<frozen importlib._bootstrap>", line 935, in _load_unlocked  
  File "<frozen importlib._bootstrap_external>", line 995, in exec_module
  File "<frozen importlib._bootstrap>", line 488, in _call_with_frames_removed
  File "C:\Users\Administrator\Desktop\Ticket\MUSEUM_BOT\ticket\urls.py", line 3, in <module>
    from . import views
  File "C:\Users\Administrator\Desktop\Ticket\MUSEUM_BOT\ticket\views.py", line 7, in <module>
    from .models import User
ImportError: cannot import name 'User' from 'ticket.models' (C:\Users\Administrator\Desktop\Ticket\MUSEUM_BOT\ticket\models.py)

During handling of the above exception, another exception occurred:

Traceback (most recent call last):
  File "C:\Users\Administrator\Desktop\Ticket\MUSEUM_BOT\manage.py", 
line 22, in <module>
    main()
  File "C:\Users\Administrator\Desktop\Ticket\MUSEUM_BOT\manage.py", 
line 18, in main
    execute_from_command_line(sys.argv)
  File "C:\Users\Administrator\AppData\Local\Programs\Python\Python312\Lib\site-packages\django\core\management\__init__.py", line 442, in execute_from_command_line
    utility.execute()
  File "C:\Users\Administrator\AppData\Local\Programs\Python\Python312\Lib\site-packages\django\core\management\__init__.py", line 436, in execute
    self.fetch_command(subcommand).run_from_argv(self.argv)
  File "C:\Users\Administrator\AppData\Local\Programs\Python\Python312\Lib\site-packages\django\core\management\base.py", line 413, in run_from_argv
    self.execute(*args, **cmd_options)
  File "C:\Users\Administrator\AppData\Local\Programs\Python\Python312\Lib\site-packages\django\core\management\base.py", line 454, in execute
    self.check()
  File "C:\Users\Administrator\AppData\Local\Programs\Python\Python312\Lib\site-packages\django\core\management\base.py", line 486, in check
    all_issues = checks.run_checks(
                 ^^^^^^^^^^^^^^^^^^
  File "C:\Users\Administrator\AppData\Local\Programs\Python\Python312\Lib\site-packages\django\core\checks\registry.py", line 88, in run_checks
    new_errors = check(app_configs=app_configs, databases=databases) 
                 ^^^^^^^^^^^^^^^^^^^^^^^^^^^^^^^^^^^^^^^^^^^^^^^^^^^ 
  File "C:\Users\Administrator\AppData\Local\Programs\Python\Python312\Lib\site-packages\django\core\checks\urls.py", line 138, in check_custom_error_handlers
    path = getattr(resolver.urlconf_module, "handler%s" % status_code)
                   ^^^^^^^^^^^^^^^^^^^^^^^
  File "C:\Users\Administrator\AppData\Local\Programs\Python\Python312\Lib\site-packages\django\utils\functional.py", line 47, in __get__ 
    res = instance.__dict__[self.name] = self.func(instance)
                                         ^^^^^^^^^^^^^^^^^^^
  File "C:\Users\Administrator\AppData\Local\Programs\Python\Python312\Lib\site-packages\django\urls\resolvers.py", line 711, in urlconf_module
    return import_module(self.urlconf_name)
           ^^^^^^^^^^^^^^^^^^^^^^^^^^^^^^^^
  File "C:\Users\Administrator\AppData\Local\Programs\Python\Python312\Lib\importlib\__init__.py", line 90, in import_module
    return _bootstrap._gcd_import(name[level:], package, level)      
           ^^^^^^^^^^^^^^^^^^^^^^^^^^^^^^^^^^^^^^^^^^^^^^^^^^^^      
  File "<frozen importlib._bootstrap>", line 1387, in _gcd_import    
  File "<frozen importlib._bootstrap>", line 1360, in _find_and_load 
  File "<frozen importlib._bootstrap>", line 1331, in _find_and_load_unlocked
  File "<frozen importlib._bootstrap>", line 935, in _load_unlocked  
  File "<frozen importlib._bootstrap_external>", line 995, in exec_module
  File "<frozen importlib._bootstrap>", line 488, in _call_with_frames_removed
  File "C:\Users\Administrator\Desktop\Ticket\MUSEUM_BOT\MUSEUM_BOT\urls.py", line 22, in <module>
    path('ticket/', include("ticket.urls"))
                    ^^^^^^^^^^^^^^^^^^^^^^
  File "C:\Users\Administrator\AppData\Local\Programs\Python\Python312\Lib\site-packages\django\urls\conf.py", line 39, in include        
    urlconf_module = import_module(urlconf_module)
                     ^^^^^^^^^^^^^^^^^^^^^^^^^^^^^
  File "C:\Users\Administrator\AppData\Local\Programs\Python\Python312\Lib\importlib\__init__.py", line 90, in import_module
    return _bootstrap._gcd_import(name[level:], package, level)      
           ^^^^^^^^^^^^^^^^^^^^^^^^^^^^^^^^^^^^^^^^^^^^^^^^^^^^      
  File "<frozen importlib._bootstrap>", line 1387, in _gcd_import    
  File "<frozen importlib._bootstrap>", line 1360, in _find_and_load 
  File "<frozen importlib._bootstrap>", line 1331, in _find_and_load_unlocked
  File "<frozen importlib._bootstrap>", line 935, in _load_unlocked
  File "<frozen importlib._bootstrap_external>", line 995, in exec_module
  File "<frozen importlib._bootstrap>", line 488, in _call_with_frames_removed
  File "C:\Users\Administrator\Desktop\Ticket\MUSEUM_BOT\ticket\urls.py", line 3, in <module>
    from . import views
  File "C:\Users\Administrator\Desktop\Ticket\MUSEUM_BOT\ticket\views.py", line 7, in <module>
    from .models import User
ImportError: cannot import name 'User' from 'ticket.models' (C:\Users\Administrator\Desktop\Ticket\MUSEUM_BOT\ticket\models.py)
PS C:\Users\Administrator\Desktop\Ticket\MUSEUM_BOT> python manage.py makemigrations ticket

ERRORS:
auth.User.groups: (fields.E304) Reverse accessor 'Group.user_set' for 'auth.User.groups' clashes with reverse accessor for 'ticket.Owner.groups'.
        HINT: Add or change a related_name argument to the definition for 'auth.User.groups' or 'ticket.Owner.groups'.
auth.User.user_permissions: (fields.E304) Reverse accessor 'Permission.user_set' for 'auth.User.user_permissions' clashes with reverse accessor for 'ticket.Owner.user_permissions'.
        HINT: Add or change a related_name argument to the definition for 'auth.User.user_permissions' or 'ticket.Owner.user_permissions'.ticket.Owner.groups: (fields.E304) Reverse accessor 'Group.user_set' for 'ticket.Owner.groups' clashes with reverse accessor for 'auth.User.groups'.
        HINT: Add or change a related_name argument to the definition for 'ticket.Owner.groups' or 'auth.User.groups'.
ticket.Owner.user_permissions: (fields.E304) Reverse accessor 'Permission.user_set' for 'ticket.Owner.user_permissions' clashes with reverse accessor for 'auth.User.user_permissions'.
        HINT: Add or change a related_name argument to the definition for 'ticket.Owner.user_permissions' or 'auth.User.user_permissions'.PS C:\Users\Administrator\Desktop\Ticket\MUSEUM_BOT> python manage.py makemigrations
SystemCheckError: System check identified some issues:

ERRORS:
auth.User.groups: (fields.E304) Reverse accessor 'Group.user_set' for 'auth.User.groups' clashes with reverse accessor for 'ticket.Owner.groups'.
        HINT: Add or change a related_name argument to the definition for 'auth.User.groups' or 'ticket.Owner.groups'.
auth.User.user_permissions: (fields.E304) Reverse accessor 'Permission.user_set' for 'auth.User.user_permissions' clashes with reverse accessor for 'ticket.Owner.user_permissions'.
        HINT: Add or change a related_name argument to the definition for 'auth.User.user_permissions' or 'ticket.Owner.user_permissions'.ticket.Owner.groups: (fields.E304) Reverse accessor 'Group.user_set' for 'ticket.Owner.groups' clashes with reverse accessor for 'auth.User.groups'.
        HINT: Add or change a related_name argument to the definition for 'ticket.Owner.groups' or 'auth.User.groups'.
ticket.Owner.user_permissions: (fields.E304) Reverse accessor 'Permission.user_set' for 'ticket.Owner.user_permissions' clashes with reverse accessor for 'auth.User.user_permissions'.
        HINT: Add or change a related_name argument to the definition for 'ticket.Owner.user_permissions' or 'auth.User.user_permissions'.PS C:\Users\Administrator\Desktop\Ticket\MUSEUM_BOT> 